[2025-05-27 12:59:56 +0000] [8] [INFO] Starting gunicorn 21.2.0
[2025-05-27 12:59:56 +0000] [8] [INFO] Listening at: http://127.0.0.1:5000 (8)
[2025-05-27 12:59:56 +0000] [8] [INFO] Using worker: gevent
[2025-05-27 12:59:56 +0000] [22] [INFO] Booting worker with pid: 22
[2025-05-27 12:59:56 +0000] [23] [INFO] Booting worker with pid: 23
[2025-05-27 12:59:56 +0000] [24] [INFO] Booting worker with pid: 24
[2025-05-27 12:59:56 +0000] [25] [INFO] Booting worker with pid: 25
[2025-05-27 13:23:58 +0000] [8] [INFO] Starting gunicorn 21.2.0
[2025-05-27 13:23:58 +0000] [8] [INFO] Listening at: http://127.0.0.1:5000 (8)
[2025-05-27 13:23:58 +0000] [8] [INFO] Using worker: gevent
[2025-05-27 13:23:58 +0000] [22] [INFO] Booting worker with pid: 22
[2025-05-27 13:23:58 +0000] [23] [INFO] Booting worker with pid: 23
[2025-05-27 13:23:58 +0000] [22] [ERROR] Exception in worker process
Traceback (most recent call last):
  File "/usr/local/lib/python3.11/site-packages/gunicorn/arbiter.py", line 609, in spawn_worker
    worker.init_process()
  File "/usr/local/lib/python3.11/site-packages/gunicorn/workers/ggevent.py", line 147, in init_process
    super().init_process()
  File "/usr/local/lib/python3.11/site-packages/gunicorn/workers/base.py", line 134, in init_process
    self.load_wsgi()
  File "/usr/local/lib/python3.11/site-packages/gunicorn/workers/base.py", line 146, in load_wsgi
    self.wsgi = self.app.wsgi()
                ^^^^^^^^^^^^^^^
  File "/usr/local/lib/python3.11/site-packages/gunicorn/app/base.py", line 67, in wsgi
    self.callable = self.load()
                    ^^^^^^^^^^^
  File "/usr/local/lib/python3.11/site-packages/gunicorn/app/wsgiapp.py", line 58, in load
    return self.load_wsgiapp()
           ^^^^^^^^^^^^^^^^^^^
  File "/usr/local/lib/python3.11/site-packages/gunicorn/app/wsgiapp.py", line 48, in load_wsgiapp
    return util.import_app(self.app_uri)
           ^^^^^^^^^^^^^^^^^^^^^^^^^^^^^
  File "/usr/local/lib/python3.11/site-packages/gunicorn/util.py", line 371, in import_app
    mod = importlib.import_module(module)
          ^^^^^^^^^^^^^^^^^^^^^^^^^^^^^^^
  File "/usr/local/lib/python3.11/importlib/__init__.py", line 126, in import_module
    return _bootstrap._gcd_import(name[level:], package, level)
           ^^^^^^^^^^^^^^^^^^^^^^^^^^^^^^^^^^^^^^^^^^^^^^^^^^^^
  File "<frozen importlib._bootstrap>", line 1204, in _gcd_import
  File "<frozen importlib._bootstrap>", line 1176, in _find_and_load
  File "<frozen importlib._bootstrap>", line 1147, in _find_and_load_unlocked
  File "<frozen importlib._bootstrap>", line 690, in _load_unlocked
  File "<frozen importlib._bootstrap_external>", line 936, in exec_module
  File "<frozen importlib._bootstrap_external>", line 1074, in get_code
  File "<frozen importlib._bootstrap_external>", line 1004, in source_to_code
  File "<frozen importlib._bootstrap>", line 241, in _call_with_frames_removed
  File "/app/gongle-web/app.py", line 15
    app.config['SQLALCHEMY_DATABASE_URI'] = os.getenv('DATABASE_URL')'sqlite:////tmp/gongle.db'
                                                                     ^^^^^^^^^^^^^^^^^^^^^^^^^^
SyntaxError: invalid syntax
[2025-05-27 13:23:58 +0000] [22] [INFO] Worker exiting (pid: 22)
[2025-05-27 13:23:58 +0000] [24] [INFO] Booting worker with pid: 24
[2025-05-27 13:23:58 +0000] [8] [ERROR] Worker (pid:22) exited with code 3
[2025-05-27 13:23:58 +0000] [23] [ERROR] Exception in worker process
Traceback (most recent call last):
  File "/usr/local/lib/python3.11/site-packages/gunicorn/arbiter.py", line 609, in spawn_worker
    worker.init_process()
  File "/usr/local/lib/python3.11/site-packages/gunicorn/workers/ggevent.py", line 147, in init_process
    super().init_process()
  File "/usr/local/lib/python3.11/site-packages/gunicorn/workers/base.py", line 134, in init_process
    self.load_wsgi()
  File "/usr/local/lib/python3.11/site-packages/gunicorn/workers/base.py", line 146, in load_wsgi
    self.wsgi = self.app.wsgi()
                ^^^^^^^^^^^^^^^
  File "/usr/local/lib/python3.11/site-packages/gunicorn/app/base.py", line 67, in wsgi
    self.callable = self.load()
                    ^^^^^^^^^^^
  File "/usr/local/lib/python3.11/site-packages/gunicorn/app/wsgiapp.py", line 58, in load
    return self.load_wsgiapp()
           ^^^^^^^^^^^^^^^^^^^
  File "/usr/local/lib/python3.11/site-packages/gunicorn/app/wsgiapp.py", line 48, in load_wsgiapp
    return util.import_app(self.app_uri)
           ^^^^^^^^^^^^^^^^^^^^^^^^^^^^^
  File "/usr/local/lib/python3.11/site-packages/gunicorn/util.py", line 371, in import_app
    mod = importlib.import_module(module)
          ^^^^^^^^^^^^^^^^^^^^^^^^^^^^^^^
  File "/usr/local/lib/python3.11/importlib/__init__.py", line 126, in import_module
    return _bootstrap._gcd_import(name[level:], package, level)
           ^^^^^^^^^^^^^^^^^^^^^^^^^^^^^^^^^^^^^^^^^^^^^^^^^^^^
  File "<frozen importlib._bootstrap>", line 1204, in _gcd_import
  File "<frozen importlib._bootstrap>", line 1176, in _find_and_load
  File "<frozen importlib._bootstrap>", line 1147, in _find_and_load_unlocked
  File "<frozen importlib._bootstrap>", line 690, in _load_unlocked
  File "<frozen importlib._bootstrap_external>", line 936, in exec_module
  File "<frozen importlib._bootstrap_external>", line 1074, in get_code
  File "<frozen importlib._bootstrap_external>", line 1004, in source_to_code
  File "<frozen importlib._bootstrap>", line 241, in _call_with_frames_removed
  File "/app/gongle-web/app.py", line 15
    app.config['SQLALCHEMY_DATABASE_URI'] = os.getenv('DATABASE_URL')'sqlite:////tmp/gongle.db'
                                                                     ^^^^^^^^^^^^^^^^^^^^^^^^^^
SyntaxError: invalid syntax
[2025-05-27 13:23:58 +0000] [23] [INFO] Worker exiting (pid: 23)
[2025-05-27 13:23:58 +0000] [24] [ERROR] Exception in worker process
Traceback (most recent call last):
  File "/usr/local/lib/python3.11/site-packages/gunicorn/arbiter.py", line 609, in spawn_worker
    worker.init_process()
  File "/usr/local/lib/python3.11/site-packages/gunicorn/workers/ggevent.py", line 147, in init_process
    super().init_process()
  File "/usr/local/lib/python3.11/site-packages/gunicorn/workers/base.py", line 134, in init_process
    self.load_wsgi()
  File "/usr/local/lib/python3.11/site-packages/gunicorn/workers/base.py", line 146, in load_wsgi
    self.wsgi = self.app.wsgi()
                ^^^^^^^^^^^^^^^
  File "/usr/local/lib/python3.11/site-packages/gunicorn/app/base.py", line 67, in wsgi
    self.callable = self.load()
                    ^^^^^^^^^^^
  File "/usr/local/lib/python3.11/site-packages/gunicorn/app/wsgiapp.py", line 58, in load
    return self.load_wsgiapp()
           ^^^^^^^^^^^^^^^^^^^
  File "/usr/local/lib/python3.11/site-packages/gunicorn/app/wsgiapp.py", line 48, in load_wsgiapp
    return util.import_app(self.app_uri)
           ^^^^^^^^^^^^^^^^^^^^^^^^^^^^^
  File "/usr/local/lib/python3.11/site-packages/gunicorn/util.py", line 371, in import_app
    mod = importlib.import_module(module)
          ^^^^^^^^^^^^^^^^^^^^^^^^^^^^^^^
  File "/usr/local/lib/python3.11/importlib/__init__.py", line 126, in import_module
    return _bootstrap._gcd_import(name[level:], package, level)
           ^^^^^^^^^^^^^^^^^^^^^^^^^^^^^^^^^^^^^^^^^^^^^^^^^^^^
  File "<frozen importlib._bootstrap>", line 1204, in _gcd_import
  File "<frozen importlib._bootstrap>", line 1176, in _find_and_load
  File "<frozen importlib._bootstrap>", line 1147, in _find_and_load_unlocked
  File "<frozen importlib._bootstrap>", line 690, in _load_unlocked
  File "<frozen importlib._bootstrap_external>", line 936, in exec_module
  File "<frozen importlib._bootstrap_external>", line 1074, in get_code
  File "<frozen importlib._bootstrap_external>", line 1004, in source_to_code
  File "<frozen importlib._bootstrap>", line 241, in _call_with_frames_removed
  File "/app/gongle-web/app.py", line 15
    app.config['SQLALCHEMY_DATABASE_URI'] = os.getenv('DATABASE_URL')'sqlite:////tmp/gongle.db'
                                                                     ^^^^^^^^^^^^^^^^^^^^^^^^^^
SyntaxError: invalid syntax
[2025-05-27 13:23:58 +0000] [24] [INFO] Worker exiting (pid: 24)
[2025-05-27 13:23:58 +0000] [8] [ERROR] Worker (pid:23) exited with code 3
Traceback (most recent call last):
  File "/usr/local/lib/python3.11/site-packages/gunicorn/arbiter.py", line 202, in run
    self.manage_workers()
  File "/usr/local/lib/python3.11/site-packages/gunicorn/arbiter.py", line 571, in manage_workers
    self.spawn_workers()
  File "/usr/local/lib/python3.11/site-packages/gunicorn/arbiter.py", line 643, in spawn_workers
    time.sleep(0.1 * random.random())
  File "/usr/local/lib/python3.11/site-packages/gunicorn/arbiter.py", line 242, in handle_chld
    self.reap_workers()
  File "/usr/local/lib/python3.11/site-packages/gunicorn/arbiter.py", line 530, in reap_workers
    raise HaltServer(reason, self.WORKER_BOOT_ERROR)
gunicorn.errors.HaltServer: <HaltServer 'Worker failed to boot.' 3>

During handling of the above exception, another exception occurred:

Traceback (most recent call last):
  File "/usr/local/bin/gunicorn", line 8, in <module>
    sys.exit(run())
             ^^^^^
  File "/usr/local/lib/python3.11/site-packages/gunicorn/app/wsgiapp.py", line 67, in run
    WSGIApplication("%(prog)s [OPTIONS] [APP_MODULE]").run()
  File "/usr/local/lib/python3.11/site-packages/gunicorn/app/base.py", line 236, in run
    super().run()
  File "/usr/local/lib/python3.11/site-packages/gunicorn/app/base.py", line 72, in run
    Arbiter(self).run()
  File "/usr/local/lib/python3.11/site-packages/gunicorn/arbiter.py", line 229, in run
    self.halt(reason=inst.reason, exit_status=inst.exit_status)
  File "/usr/local/lib/python3.11/site-packages/gunicorn/arbiter.py", line 342, in halt
    self.stop()
  File "/usr/local/lib/python3.11/site-packages/gunicorn/arbiter.py", line 396, in stop
    time.sleep(0.1)
  File "/usr/local/lib/python3.11/site-packages/gunicorn/arbiter.py", line 242, in handle_chld
    self.reap_workers()
  File "/usr/local/lib/python3.11/site-packages/gunicorn/arbiter.py", line 530, in reap_workers
    raise HaltServer(reason, self.WORKER_BOOT_ERROR)
gunicorn.errors.HaltServer: <HaltServer 'Worker failed to boot.' 3>
[2025-05-27 13:23:59 +0000] [25] [INFO] Starting gunicorn 21.2.0
[2025-05-27 13:23:59 +0000] [25] [INFO] Listening at: http://127.0.0.1:5000 (25)
[2025-05-27 13:23:59 +0000] [25] [INFO] Using worker: gevent
[2025-05-27 13:23:59 +0000] [26] [INFO] Booting worker with pid: 26
[2025-05-27 13:23:59 +0000] [27] [INFO] Booting worker with pid: 27
[2025-05-27 13:23:59 +0000] [26] [ERROR] Exception in worker process
Traceback (most recent call last):
  File "/usr/local/lib/python3.11/site-packages/gunicorn/arbiter.py", line 609, in spawn_worker
    worker.init_process()
  File "/usr/local/lib/python3.11/site-packages/gunicorn/workers/ggevent.py", line 147, in init_process
    super().init_process()
  File "/usr/local/lib/python3.11/site-packages/gunicorn/workers/base.py", line 134, in init_process
    self.load_wsgi()
  File "/usr/local/lib/python3.11/site-packages/gunicorn/workers/base.py", line 146, in load_wsgi
    self.wsgi = self.app.wsgi()
                ^^^^^^^^^^^^^^^
  File "/usr/local/lib/python3.11/site-packages/gunicorn/app/base.py", line 67, in wsgi
    self.callable = self.load()
                    ^^^^^^^^^^^
  File "/usr/local/lib/python3.11/site-packages/gunicorn/app/wsgiapp.py", line 58, in load
    return self.load_wsgiapp()
           ^^^^^^^^^^^^^^^^^^^
  File "/usr/local/lib/python3.11/site-packages/gunicorn/app/wsgiapp.py", line 48, in load_wsgiapp
    return util.import_app(self.app_uri)
           ^^^^^^^^^^^^^^^^^^^^^^^^^^^^^
  File "/usr/local/lib/python3.11/site-packages/gunicorn/util.py", line 371, in import_app
    mod = importlib.import_module(module)
          ^^^^^^^^^^^^^^^^^^^^^^^^^^^^^^^
  File "/usr/local/lib/python3.11/importlib/__init__.py", line 126, in import_module
    return _bootstrap._gcd_import(name[level:], package, level)
           ^^^^^^^^^^^^^^^^^^^^^^^^^^^^^^^^^^^^^^^^^^^^^^^^^^^^
  File "<frozen importlib._bootstrap>", line 1204, in _gcd_import
  File "<frozen importlib._bootstrap>", line 1176, in _find_and_load
  File "<frozen importlib._bootstrap>", line 1147, in _find_and_load_unlocked
  File "<frozen importlib._bootstrap>", line 690, in _load_unlocked
  File "<frozen importlib._bootstrap_external>", line 936, in exec_module
  File "<frozen importlib._bootstrap_external>", line 1074, in get_code
  File "<frozen importlib._bootstrap_external>", line 1004, in source_to_code
  File "<frozen importlib._bootstrap>", line 241, in _call_with_frames_removed
  File "/app/gongle-web/app.py", line 15
    app.config['SQLALCHEMY_DATABASE_URI'] = os.getenv('DATABASE_URL')'sqlite:////tmp/gongle.db'
                                                                     ^^^^^^^^^^^^^^^^^^^^^^^^^^
SyntaxError: invalid syntax
[2025-05-27 13:23:59 +0000] [26] [INFO] Worker exiting (pid: 26)
[2025-05-27 13:23:59 +0000] [28] [INFO] Booting worker with pid: 28
[2025-05-27 13:23:59 +0000] [25] [ERROR] Worker (pid:26) exited with code 3
[2025-05-27 13:23:59 +0000] [27] [ERROR] Exception in worker process
Traceback (most recent call last):
  File "/usr/local/lib/python3.11/site-packages/gunicorn/arbiter.py", line 609, in spawn_worker
    worker.init_process()
  File "/usr/local/lib/python3.11/site-packages/gunicorn/workers/ggevent.py", line 147, in init_process
    super().init_process()
  File "/usr/local/lib/python3.11/site-packages/gunicorn/workers/base.py", line 134, in init_process
    self.load_wsgi()
  File "/usr/local/lib/python3.11/site-packages/gunicorn/workers/base.py", line 146, in load_wsgi
    self.wsgi = self.app.wsgi()
                ^^^^^^^^^^^^^^^
  File "/usr/local/lib/python3.11/site-packages/gunicorn/app/base.py", line 67, in wsgi
    self.callable = self.load()
                    ^^^^^^^^^^^
  File "/usr/local/lib/python3.11/site-packages/gunicorn/app/wsgiapp.py", line 58, in load
    return self.load_wsgiapp()
           ^^^^^^^^^^^^^^^^^^^
  File "/usr/local/lib/python3.11/site-packages/gunicorn/app/wsgiapp.py", line 48, in load_wsgiapp
    return util.import_app(self.app_uri)
           ^^^^^^^^^^^^^^^^^^^^^^^^^^^^^
  File "/usr/local/lib/python3.11/site-packages/gunicorn/util.py", line 371, in import_app
    mod = importlib.import_module(module)
          ^^^^^^^^^^^^^^^^^^^^^^^^^^^^^^^
  File "/usr/local/lib/python3.11/importlib/__init__.py", line 126, in import_module
    return _bootstrap._gcd_import(name[level:], package, level)
           ^^^^^^^^^^^^^^^^^^^^^^^^^^^^^^^^^^^^^^^^^^^^^^^^^^^^
  File "<frozen importlib._bootstrap>", line 1204, in _gcd_import
  File "<frozen importlib._bootstrap>", line 1176, in _find_and_load
  File "<frozen importlib._bootstrap>", line 1147, in _find_and_load_unlocked
  File "<frozen importlib._bootstrap>", line 690, in _load_unlocked
  File "<frozen importlib._bootstrap_external>", line 936, in exec_module
  File "<frozen importlib._bootstrap_external>", line 1074, in get_code
  File "<frozen importlib._bootstrap_external>", line 1004, in source_to_code
  File "<frozen importlib._bootstrap>", line 241, in _call_with_frames_removed
  File "/app/gongle-web/app.py", line 15
    app.config['SQLALCHEMY_DATABASE_URI'] = os.getenv('DATABASE_URL')'sqlite:////tmp/gongle.db'
                                                                     ^^^^^^^^^^^^^^^^^^^^^^^^^^
SyntaxError: invalid syntax
[2025-05-27 13:23:59 +0000] [27] [INFO] Worker exiting (pid: 27)
[2025-05-27 13:23:59 +0000] [25] [ERROR] Worker (pid:27) exited with code 3
Traceback (most recent call last):
  File "/usr/local/lib/python3.11/site-packages/gunicorn/arbiter.py", line 202, in run
    self.manage_workers()
  File "/usr/local/lib/python3.11/site-packages/gunicorn/arbiter.py", line 571, in manage_workers
    self.spawn_workers()
  File "/usr/local/lib/python3.11/site-packages/gunicorn/arbiter.py", line 643, in spawn_workers
    time.sleep(0.1 * random.random())
  File "/usr/local/lib/python3.11/site-packages/gunicorn/arbiter.py", line 242, in handle_chld
    self.reap_workers()
  File "/usr/local/lib/python3.11/site-packages/gunicorn/arbiter.py", line 530, in reap_workers
    raise HaltServer(reason, self.WORKER_BOOT_ERROR)
gunicorn.errors.HaltServer: <HaltServer 'Worker failed to boot.' 3>

During handling of the above exception, another exception occurred:

Traceback (most recent call last):
  File "/usr/local/bin/gunicorn", line 8, in <module>
    sys.exit(run())
             ^^^^^
  File "/usr/local/lib/python3.11/site-packages/gunicorn/app/wsgiapp.py", line 67, in run
    WSGIApplication("%(prog)s [OPTIONS] [APP_MODULE]").run()
  File "/usr/local/lib/python3.11/site-packages/gunicorn/app/base.py", line 236, in run
    super().run()
  File "/usr/local/lib/python3.11/site-packages/gunicorn/app/base.py", line 72, in run
    Arbiter(self).run()
  File "/usr/local/lib/python3.11/site-packages/gunicorn/arbiter.py", line 229, in run
    self.halt(reason=inst.reason, exit_status=inst.exit_status)
  File "/usr/local/lib/python3.11/site-packages/gunicorn/arbiter.py", line 342, in halt
    self.stop()
  File "/usr/local/lib/python3.11/site-packages/gunicorn/arbiter.py", line 396, in stop
    time.sleep(0.1)
  File "/usr/local/lib/python3.11/site-packages/gunicorn/arbiter.py", line 242, in handle_chld
    self.reap_workers()
  File "/usr/local/lib/python3.11/site-packages/gunicorn/arbiter.py", line 530, in reap_workers
    raise HaltServer(reason, self.WORKER_BOOT_ERROR)
gunicorn.errors.HaltServer: <HaltServer 'Worker failed to boot.' 3>
[2025-05-27 13:23:59 +0000] [28] [ERROR] Exception in worker process
Traceback (most recent call last):
  File "/usr/local/lib/python3.11/site-packages/gunicorn/arbiter.py", line 609, in spawn_worker
    worker.init_process()
  File "/usr/local/lib/python3.11/site-packages/gunicorn/workers/ggevent.py", line 147, in init_process
    super().init_process()
  File "/usr/local/lib/python3.11/site-packages/gunicorn/workers/base.py", line 134, in init_process
    self.load_wsgi()
  File "/usr/local/lib/python3.11/site-packages/gunicorn/workers/base.py", line 146, in load_wsgi
    self.wsgi = self.app.wsgi()
                ^^^^^^^^^^^^^^^
  File "/usr/local/lib/python3.11/site-packages/gunicorn/app/base.py", line 67, in wsgi
    self.callable = self.load()
                    ^^^^^^^^^^^
  File "/usr/local/lib/python3.11/site-packages/gunicorn/app/wsgiapp.py", line 58, in load
    return self.load_wsgiapp()
           ^^^^^^^^^^^^^^^^^^^
  File "/usr/local/lib/python3.11/site-packages/gunicorn/app/wsgiapp.py", line 48, in load_wsgiapp
    return util.import_app(self.app_uri)
           ^^^^^^^^^^^^^^^^^^^^^^^^^^^^^
  File "/usr/local/lib/python3.11/site-packages/gunicorn/util.py", line 371, in import_app
    mod = importlib.import_module(module)
          ^^^^^^^^^^^^^^^^^^^^^^^^^^^^^^^
  File "/usr/local/lib/python3.11/importlib/__init__.py", line 126, in import_module
    return _bootstrap._gcd_import(name[level:], package, level)
           ^^^^^^^^^^^^^^^^^^^^^^^^^^^^^^^^^^^^^^^^^^^^^^^^^^^^
  File "<frozen importlib._bootstrap>", line 1204, in _gcd_import
  File "<frozen importlib._bootstrap>", line 1176, in _find_and_load
  File "<frozen importlib._bootstrap>", line 1147, in _find_and_load_unlocked
  File "<frozen importlib._bootstrap>", line 690, in _load_unlocked
  File "<frozen importlib._bootstrap_external>", line 936, in exec_module
  File "<frozen importlib._bootstrap_external>", line 1074, in get_code
  File "<frozen importlib._bootstrap_external>", line 1004, in source_to_code
  File "<frozen importlib._bootstrap>", line 241, in _call_with_frames_removed
  File "/app/gongle-web/app.py", line 15
    app.config['SQLALCHEMY_DATABASE_URI'] = os.getenv('DATABASE_URL')'sqlite:////tmp/gongle.db'
                                                                     ^^^^^^^^^^^^^^^^^^^^^^^^^^
SyntaxError: invalid syntax
[2025-05-27 13:23:59 +0000] [28] [INFO] Worker exiting (pid: 28)
[2025-05-27 13:24:01 +0000] [29] [INFO] Starting gunicorn 21.2.0
[2025-05-27 13:24:01 +0000] [29] [INFO] Listening at: http://127.0.0.1:5000 (29)
[2025-05-27 13:24:01 +0000] [29] [INFO] Using worker: gevent
[2025-05-27 13:24:01 +0000] [30] [INFO] Booting worker with pid: 30
[2025-05-27 13:24:01 +0000] [31] [INFO] Booting worker with pid: 31
[2025-05-27 13:24:01 +0000] [30] [ERROR] Exception in worker process
Traceback (most recent call last):
  File "/usr/local/lib/python3.11/site-packages/gunicorn/arbiter.py", line 609, in spawn_worker
    worker.init_process()
  File "/usr/local/lib/python3.11/site-packages/gunicorn/workers/ggevent.py", line 147, in init_process
    super().init_process()
  File "/usr/local/lib/python3.11/site-packages/gunicorn/workers/base.py", line 134, in init_process
    self.load_wsgi()
  File "/usr/local/lib/python3.11/site-packages/gunicorn/workers/base.py", line 146, in load_wsgi
    self.wsgi = self.app.wsgi()
                ^^^^^^^^^^^^^^^
  File "/usr/local/lib/python3.11/site-packages/gunicorn/app/base.py", line 67, in wsgi
    self.callable = self.load()
                    ^^^^^^^^^^^
  File "/usr/local/lib/python3.11/site-packages/gunicorn/app/wsgiapp.py", line 58, in load
    return self.load_wsgiapp()
           ^^^^^^^^^^^^^^^^^^^
  File "/usr/local/lib/python3.11/site-packages/gunicorn/app/wsgiapp.py", line 48, in load_wsgiapp
    return util.import_app(self.app_uri)
           ^^^^^^^^^^^^^^^^^^^^^^^^^^^^^
  File "/usr/local/lib/python3.11/site-packages/gunicorn/util.py", line 371, in import_app
    mod = importlib.import_module(module)
          ^^^^^^^^^^^^^^^^^^^^^^^^^^^^^^^
  File "/usr/local/lib/python3.11/importlib/__init__.py", line 126, in import_module
    return _bootstrap._gcd_import(name[level:], package, level)
           ^^^^^^^^^^^^^^^^^^^^^^^^^^^^^^^^^^^^^^^^^^^^^^^^^^^^
  File "<frozen importlib._bootstrap>", line 1204, in _gcd_import
  File "<frozen importlib._bootstrap>", line 1176, in _find_and_load
  File "<frozen importlib._bootstrap>", line 1147, in _find_and_load_unlocked
  File "<frozen importlib._bootstrap>", line 690, in _load_unlocked
  File "<frozen importlib._bootstrap_external>", line 936, in exec_module
  File "<frozen importlib._bootstrap_external>", line 1074, in get_code
  File "<frozen importlib._bootstrap_external>", line 1004, in source_to_code
  File "<frozen importlib._bootstrap>", line 241, in _call_with_frames_removed
  File "/app/gongle-web/app.py", line 15
    app.config['SQLALCHEMY_DATABASE_URI'] = os.getenv('DATABASE_URL')'sqlite:////tmp/gongle.db'
                                                                     ^^^^^^^^^^^^^^^^^^^^^^^^^^
SyntaxError: invalid syntax
[2025-05-27 13:24:01 +0000] [30] [INFO] Worker exiting (pid: 30)
[2025-05-27 13:24:01 +0000] [32] [INFO] Booting worker with pid: 32
[2025-05-27 13:24:01 +0000] [31] [ERROR] Exception in worker process
Traceback (most recent call last):
  File "/usr/local/lib/python3.11/site-packages/gunicorn/arbiter.py", line 609, in spawn_worker
    worker.init_process()
  File "/usr/local/lib/python3.11/site-packages/gunicorn/workers/ggevent.py", line 147, in init_process
    super().init_process()
  File "/usr/local/lib/python3.11/site-packages/gunicorn/workers/base.py", line 134, in init_process
    self.load_wsgi()
  File "/usr/local/lib/python3.11/site-packages/gunicorn/workers/base.py", line 146, in load_wsgi
    self.wsgi = self.app.wsgi()
                ^^^^^^^^^^^^^^^
  File "/usr/local/lib/python3.11/site-packages/gunicorn/app/base.py", line 67, in wsgi
    self.callable = self.load()
                    ^^^^^^^^^^^
  File "/usr/local/lib/python3.11/site-packages/gunicorn/app/wsgiapp.py", line 58, in load
    return self.load_wsgiapp()
           ^^^^^^^^^^^^^^^^^^^
  File "/usr/local/lib/python3.11/site-packages/gunicorn/app/wsgiapp.py", line 48, in load_wsgiapp
    return util.import_app(self.app_uri)
           ^^^^^^^^^^^^^^^^^^^^^^^^^^^^^
  File "/usr/local/lib/python3.11/site-packages/gunicorn/util.py", line 371, in import_app
    mod = importlib.import_module(module)
          ^^^^^^^^^^^^^^^^^^^^^^^^^^^^^^^
  File "/usr/local/lib/python3.11/importlib/__init__.py", line 126, in import_module
    return _bootstrap._gcd_import(name[level:], package, level)
           ^^^^^^^^^^^^^^^^^^^^^^^^^^^^^^^^^^^^^^^^^^^^^^^^^^^^
  File "<frozen importlib._bootstrap>", line 1204, in _gcd_import
  File "<frozen importlib._bootstrap>", line 1176, in _find_and_load
  File "<frozen importlib._bootstrap>", line 1147, in _find_and_load_unlocked
  File "<frozen importlib._bootstrap>", line 690, in _load_unlocked
  File "<frozen importlib._bootstrap_external>", line 936, in exec_module
  File "<frozen importlib._bootstrap_external>", line 1074, in get_code
  File "<frozen importlib._bootstrap_external>", line 1004, in source_to_code
  File "<frozen importlib._bootstrap>", line 241, in _call_with_frames_removed
  File "/app/gongle-web/app.py", line 15
    app.config['SQLALCHEMY_DATABASE_URI'] = os.getenv('DATABASE_URL')'sqlite:////tmp/gongle.db'
                                                                     ^^^^^^^^^^^^^^^^^^^^^^^^^^
SyntaxError: invalid syntax
[2025-05-27 13:24:01 +0000] [31] [INFO] Worker exiting (pid: 31)
[2025-05-27 13:24:01 +0000] [29] [ERROR] Worker (pid:30) exited with code 3
[2025-05-27 13:24:01 +0000] [29] [ERROR] Worker (pid:31) was sent SIGTERM!
[2025-05-27 13:24:01 +0000] [32] [ERROR] Exception in worker process
Traceback (most recent call last):
  File "/usr/local/lib/python3.11/site-packages/gunicorn/arbiter.py", line 609, in spawn_worker
    worker.init_process()
  File "/usr/local/lib/python3.11/site-packages/gunicorn/workers/ggevent.py", line 147, in init_process
    super().init_process()
  File "/usr/local/lib/python3.11/site-packages/gunicorn/workers/base.py", line 134, in init_process
    self.load_wsgi()
  File "/usr/local/lib/python3.11/site-packages/gunicorn/workers/base.py", line 146, in load_wsgi
    self.wsgi = self.app.wsgi()
                ^^^^^^^^^^^^^^^
  File "/usr/local/lib/python3.11/site-packages/gunicorn/app/base.py", line 67, in wsgi
    self.callable = self.load()
                    ^^^^^^^^^^^
  File "/usr/local/lib/python3.11/site-packages/gunicorn/app/wsgiapp.py", line 58, in load
    return self.load_wsgiapp()
           ^^^^^^^^^^^^^^^^^^^
  File "/usr/local/lib/python3.11/site-packages/gunicorn/app/wsgiapp.py", line 48, in load_wsgiapp
    return util.import_app(self.app_uri)
           ^^^^^^^^^^^^^^^^^^^^^^^^^^^^^
  File "/usr/local/lib/python3.11/site-packages/gunicorn/util.py", line 371, in import_app
    mod = importlib.import_module(module)
          ^^^^^^^^^^^^^^^^^^^^^^^^^^^^^^^
  File "/usr/local/lib/python3.11/importlib/__init__.py", line 126, in import_module
    return _bootstrap._gcd_import(name[level:], package, level)
           ^^^^^^^^^^^^^^^^^^^^^^^^^^^^^^^^^^^^^^^^^^^^^^^^^^^^
  File "<frozen importlib._bootstrap>", line 1204, in _gcd_import
  File "<frozen importlib._bootstrap>", line 1176, in _find_and_load
  File "<frozen importlib._bootstrap>", line 1147, in _find_and_load_unlocked
  File "<frozen importlib._bootstrap>", line 690, in _load_unlocked
  File "<frozen importlib._bootstrap_external>", line 936, in exec_module
  File "<frozen importlib._bootstrap_external>", line 1074, in get_code
  File "<frozen importlib._bootstrap_external>", line 1004, in source_to_code
  File "<frozen importlib._bootstrap>", line 241, in _call_with_frames_removed
  File "/app/gongle-web/app.py", line 15
    app.config['SQLALCHEMY_DATABASE_URI'] = os.getenv('DATABASE_URL')'sqlite:////tmp/gongle.db'
                                                                     ^^^^^^^^^^^^^^^^^^^^^^^^^^
SyntaxError: invalid syntax
[2025-05-27 13:24:01 +0000] [32] [INFO] Worker exiting (pid: 32)
[2025-05-27 13:24:01 +0000] [29] [ERROR] Worker (pid:32) exited with code 3
Traceback (most recent call last):
  File "/usr/local/lib/python3.11/site-packages/gunicorn/arbiter.py", line 202, in run
    self.manage_workers()
  File "/usr/local/lib/python3.11/site-packages/gunicorn/arbiter.py", line 571, in manage_workers
    self.spawn_workers()
  File "/usr/local/lib/python3.11/site-packages/gunicorn/arbiter.py", line 643, in spawn_workers
    time.sleep(0.1 * random.random())
  File "/usr/local/lib/python3.11/site-packages/gunicorn/arbiter.py", line 242, in handle_chld
    self.reap_workers()
  File "/usr/local/lib/python3.11/site-packages/gunicorn/arbiter.py", line 530, in reap_workers
    raise HaltServer(reason, self.WORKER_BOOT_ERROR)
gunicorn.errors.HaltServer: <HaltServer 'Worker failed to boot.' 3>

During handling of the above exception, another exception occurred:

Traceback (most recent call last):
  File "/usr/local/bin/gunicorn", line 8, in <module>
    sys.exit(run())
             ^^^^^
  File "/usr/local/lib/python3.11/site-packages/gunicorn/app/wsgiapp.py", line 67, in run
    WSGIApplication("%(prog)s [OPTIONS] [APP_MODULE]").run()
  File "/usr/local/lib/python3.11/site-packages/gunicorn/app/base.py", line 236, in run
    super().run()
  File "/usr/local/lib/python3.11/site-packages/gunicorn/app/base.py", line 72, in run
    Arbiter(self).run()
  File "/usr/local/lib/python3.11/site-packages/gunicorn/arbiter.py", line 229, in run
    self.halt(reason=inst.reason, exit_status=inst.exit_status)
  File "/usr/local/lib/python3.11/site-packages/gunicorn/arbiter.py", line 342, in halt
    self.stop()
  File "/usr/local/lib/python3.11/site-packages/gunicorn/arbiter.py", line 396, in stop
    time.sleep(0.1)
  File "/usr/local/lib/python3.11/site-packages/gunicorn/arbiter.py", line 242, in handle_chld
    self.reap_workers()
  File "/usr/local/lib/python3.11/site-packages/gunicorn/arbiter.py", line 530, in reap_workers
    raise HaltServer(reason, self.WORKER_BOOT_ERROR)
gunicorn.errors.HaltServer: <HaltServer 'Worker failed to boot.' 3>
[2025-05-27 13:24:04 +0000] [33] [INFO] Starting gunicorn 21.2.0
[2025-05-27 13:24:04 +0000] [33] [INFO] Listening at: http://127.0.0.1:5000 (33)
[2025-05-27 13:24:04 +0000] [33] [INFO] Using worker: gevent
[2025-05-27 13:24:05 +0000] [34] [INFO] Booting worker with pid: 34
[2025-05-27 13:24:05 +0000] [35] [INFO] Booting worker with pid: 35
[2025-05-27 13:24:05 +0000] [34] [ERROR] Exception in worker process
Traceback (most recent call last):
  File "/usr/local/lib/python3.11/site-packages/gunicorn/arbiter.py", line 609, in spawn_worker
    worker.init_process()
  File "/usr/local/lib/python3.11/site-packages/gunicorn/workers/ggevent.py", line 147, in init_process
    super().init_process()
  File "/usr/local/lib/python3.11/site-packages/gunicorn/workers/base.py", line 134, in init_process
    self.load_wsgi()
  File "/usr/local/lib/python3.11/site-packages/gunicorn/workers/base.py", line 146, in load_wsgi
    self.wsgi = self.app.wsgi()
                ^^^^^^^^^^^^^^^
  File "/usr/local/lib/python3.11/site-packages/gunicorn/app/base.py", line 67, in wsgi
    self.callable = self.load()
                    ^^^^^^^^^^^
  File "/usr/local/lib/python3.11/site-packages/gunicorn/app/wsgiapp.py", line 58, in load
    return self.load_wsgiapp()
           ^^^^^^^^^^^^^^^^^^^
  File "/usr/local/lib/python3.11/site-packages/gunicorn/app/wsgiapp.py", line 48, in load_wsgiapp
    return util.import_app(self.app_uri)
           ^^^^^^^^^^^^^^^^^^^^^^^^^^^^^
  File "/usr/local/lib/python3.11/site-packages/gunicorn/util.py", line 371, in import_app
    mod = importlib.import_module(module)
          ^^^^^^^^^^^^^^^^^^^^^^^^^^^^^^^
  File "/usr/local/lib/python3.11/importlib/__init__.py", line 126, in import_module
    return _bootstrap._gcd_import(name[level:], package, level)
           ^^^^^^^^^^^^^^^^^^^^^^^^^^^^^^^^^^^^^^^^^^^^^^^^^^^^
  File "<frozen importlib._bootstrap>", line 1204, in _gcd_import
  File "<frozen importlib._bootstrap>", line 1176, in _find_and_load
  File "<frozen importlib._bootstrap>", line 1147, in _find_and_load_unlocked
  File "<frozen importlib._bootstrap>", line 690, in _load_unlocked
  File "<frozen importlib._bootstrap_external>", line 936, in exec_module
  File "<frozen importlib._bootstrap_external>", line 1074, in get_code
  File "<frozen importlib._bootstrap_external>", line 1004, in source_to_code
  File "<frozen importlib._bootstrap>", line 241, in _call_with_frames_removed
  File "/app/gongle-web/app.py", line 15
    app.config['SQLALCHEMY_DATABASE_URI'] = os.getenv('DATABASE_URL')'sqlite:////tmp/gongle.db'
                                                                     ^^^^^^^^^^^^^^^^^^^^^^^^^^
SyntaxError: invalid syntax
[2025-05-27 13:24:05 +0000] [34] [INFO] Worker exiting (pid: 34)
[2025-05-27 13:24:05 +0000] [36] [INFO] Booting worker with pid: 36
[2025-05-27 13:24:05 +0000] [33] [ERROR] Worker (pid:34) exited with code 3
[2025-05-27 13:24:05 +0000] [35] [ERROR] Exception in worker process
Traceback (most recent call last):
  File "/usr/local/lib/python3.11/site-packages/gunicorn/arbiter.py", line 609, in spawn_worker
    worker.init_process()
  File "/usr/local/lib/python3.11/site-packages/gunicorn/workers/ggevent.py", line 147, in init_process
    super().init_process()
  File "/usr/local/lib/python3.11/site-packages/gunicorn/workers/base.py", line 134, in init_process
    self.load_wsgi()
  File "/usr/local/lib/python3.11/site-packages/gunicorn/workers/base.py", line 146, in load_wsgi
    self.wsgi = self.app.wsgi()
                ^^^^^^^^^^^^^^^
  File "/usr/local/lib/python3.11/site-packages/gunicorn/app/base.py", line 67, in wsgi
    self.callable = self.load()
                    ^^^^^^^^^^^
  File "/usr/local/lib/python3.11/site-packages/gunicorn/app/wsgiapp.py", line 58, in load
    return self.load_wsgiapp()
           ^^^^^^^^^^^^^^^^^^^
  File "/usr/local/lib/python3.11/site-packages/gunicorn/app/wsgiapp.py", line 48, in load_wsgiapp
    return util.import_app(self.app_uri)
           ^^^^^^^^^^^^^^^^^^^^^^^^^^^^^
  File "/usr/local/lib/python3.11/site-packages/gunicorn/util.py", line 371, in import_app
    mod = importlib.import_module(module)
          ^^^^^^^^^^^^^^^^^^^^^^^^^^^^^^^
  File "/usr/local/lib/python3.11/importlib/__init__.py", line 126, in import_module
    return _bootstrap._gcd_import(name[level:], package, level)
           ^^^^^^^^^^^^^^^^^^^^^^^^^^^^^^^^^^^^^^^^^^^^^^^^^^^^
  File "<frozen importlib._bootstrap>", line 1204, in _gcd_import
  File "<frozen importlib._bootstrap>", line 1176, in _find_and_load
  File "<frozen importlib._bootstrap>", line 1147, in _find_and_load_unlocked
  File "<frozen importlib._bootstrap>", line 690, in _load_unlocked
  File "<frozen importlib._bootstrap_external>", line 936, in exec_module
  File "<frozen importlib._bootstrap_external>", line 1074, in get_code
  File "<frozen importlib._bootstrap_external>", line 1004, in source_to_code
  File "<frozen importlib._bootstrap>", line 241, in _call_with_frames_removed
  File "/app/gongle-web/app.py", line 15
    app.config['SQLALCHEMY_DATABASE_URI'] = os.getenv('DATABASE_URL')'sqlite:////tmp/gongle.db'
                                                                     ^^^^^^^^^^^^^^^^^^^^^^^^^^
SyntaxError: invalid syntax
[2025-05-27 13:24:05 +0000] [35] [INFO] Worker exiting (pid: 35)
[2025-05-27 13:24:05 +0000] [33] [ERROR] Worker (pid:35) exited with code 3
Traceback (most recent call last):
  File "/usr/local/lib/python3.11/site-packages/gunicorn/arbiter.py", line 202, in run
    self.manage_workers()
  File "/usr/local/lib/python3.11/site-packages/gunicorn/arbiter.py", line 571, in manage_workers
    self.spawn_workers()
  File "/usr/local/lib/python3.11/site-packages/gunicorn/arbiter.py", line 643, in spawn_workers
    time.sleep(0.1 * random.random())
  File "/usr/local/lib/python3.11/site-packages/gunicorn/arbiter.py", line 242, in handle_chld
    self.reap_workers()
  File "/usr/local/lib/python3.11/site-packages/gunicorn/arbiter.py", line 530, in reap_workers
    raise HaltServer(reason, self.WORKER_BOOT_ERROR)
gunicorn.errors.HaltServer: <HaltServer 'Worker failed to boot.' 3>

During handling of the above exception, another exception occurred:

Traceback (most recent call last):
  File "/usr/local/bin/gunicorn", line 8, in <module>
    sys.exit(run())
             ^^^^^
  File "/usr/local/lib/python3.11/site-packages/gunicorn/app/wsgiapp.py", line 67, in run
    WSGIApplication("%(prog)s [OPTIONS] [APP_MODULE]").run()
  File "/usr/local/lib/python3.11/site-packages/gunicorn/app/base.py", line 236, in run
    super().run()
  File "/usr/local/lib/python3.11/site-packages/gunicorn/app/base.py", line 72, in run
    Arbiter(self).run()
  File "/usr/local/lib/python3.11/site-packages/gunicorn/arbiter.py", line 229, in run
    self.halt(reason=inst.reason, exit_status=inst.exit_status)
  File "/usr/local/lib/python3.11/site-packages/gunicorn/arbiter.py", line 342, in halt
    self.stop()
  File "/usr/local/lib/python3.11/site-packages/gunicorn/arbiter.py", line 396, in stop
    time.sleep(0.1)
  File "/usr/local/lib/python3.11/site-packages/gunicorn/arbiter.py", line 242, in handle_chld
    self.reap_workers()
  File "/usr/local/lib/python3.11/site-packages/gunicorn/arbiter.py", line 530, in reap_workers
    raise HaltServer(reason, self.WORKER_BOOT_ERROR)
gunicorn.errors.HaltServer: <HaltServer 'Worker failed to boot.' 3>
[2025-05-27 13:24:05 +0000] [36] [ERROR] Exception in worker process
Traceback (most recent call last):
  File "/usr/local/lib/python3.11/site-packages/gunicorn/arbiter.py", line 609, in spawn_worker
    worker.init_process()
  File "/usr/local/lib/python3.11/site-packages/gunicorn/workers/ggevent.py", line 147, in init_process
    super().init_process()
  File "/usr/local/lib/python3.11/site-packages/gunicorn/workers/base.py", line 134, in init_process
    self.load_wsgi()
  File "/usr/local/lib/python3.11/site-packages/gunicorn/workers/base.py", line 146, in load_wsgi
    self.wsgi = self.app.wsgi()
                ^^^^^^^^^^^^^^^
  File "/usr/local/lib/python3.11/site-packages/gunicorn/app/base.py", line 67, in wsgi
    self.callable = self.load()
                    ^^^^^^^^^^^
  File "/usr/local/lib/python3.11/site-packages/gunicorn/app/wsgiapp.py", line 58, in load
    return self.load_wsgiapp()
           ^^^^^^^^^^^^^^^^^^^
  File "/usr/local/lib/python3.11/site-packages/gunicorn/app/wsgiapp.py", line 48, in load_wsgiapp
    return util.import_app(self.app_uri)
           ^^^^^^^^^^^^^^^^^^^^^^^^^^^^^
  File "/usr/local/lib/python3.11/site-packages/gunicorn/util.py", line 371, in import_app
    mod = importlib.import_module(module)
          ^^^^^^^^^^^^^^^^^^^^^^^^^^^^^^^
  File "/usr/local/lib/python3.11/importlib/__init__.py", line 126, in import_module
    return _bootstrap._gcd_import(name[level:], package, level)
           ^^^^^^^^^^^^^^^^^^^^^^^^^^^^^^^^^^^^^^^^^^^^^^^^^^^^
  File "<frozen importlib._bootstrap>", line 1204, in _gcd_import
  File "<frozen importlib._bootstrap>", line 1176, in _find_and_load
  File "<frozen importlib._bootstrap>", line 1147, in _find_and_load_unlocked
  File "<frozen importlib._bootstrap>", line 690, in _load_unlocked
  File "<frozen importlib._bootstrap_external>", line 936, in exec_module
  File "<frozen importlib._bootstrap_external>", line 1074, in get_code
  File "<frozen importlib._bootstrap_external>", line 1004, in source_to_code
  File "<frozen importlib._bootstrap>", line 241, in _call_with_frames_removed
  File "/app/gongle-web/app.py", line 15
    app.config['SQLALCHEMY_DATABASE_URI'] = os.getenv('DATABASE_URL')'sqlite:////tmp/gongle.db'
                                                                     ^^^^^^^^^^^^^^^^^^^^^^^^^^
SyntaxError: invalid syntax
[2025-05-27 13:24:05 +0000] [36] [INFO] Worker exiting (pid: 36)
[2025-05-27 13:25:01 +0000] [8] [INFO] Starting gunicorn 21.2.0
[2025-05-27 13:25:01 +0000] [8] [INFO] Listening at: http://127.0.0.1:5000 (8)
[2025-05-27 13:25:01 +0000] [8] [INFO] Using worker: gevent
[2025-05-27 13:25:01 +0000] [22] [INFO] Booting worker with pid: 22
[2025-05-27 13:25:01 +0000] [23] [INFO] Booting worker with pid: 23
[2025-05-27 13:25:01 +0000] [22] [ERROR] Exception in worker process
Traceback (most recent call last):
  File "/usr/local/lib/python3.11/site-packages/gunicorn/arbiter.py", line 609, in spawn_worker
    worker.init_process()
  File "/usr/local/lib/python3.11/site-packages/gunicorn/workers/ggevent.py", line 147, in init_process
    super().init_process()
  File "/usr/local/lib/python3.11/site-packages/gunicorn/workers/base.py", line 134, in init_process
    self.load_wsgi()
  File "/usr/local/lib/python3.11/site-packages/gunicorn/workers/base.py", line 146, in load_wsgi
    self.wsgi = self.app.wsgi()
                ^^^^^^^^^^^^^^^
  File "/usr/local/lib/python3.11/site-packages/gunicorn/app/base.py", line 67, in wsgi
    self.callable = self.load()
                    ^^^^^^^^^^^
  File "/usr/local/lib/python3.11/site-packages/gunicorn/app/wsgiapp.py", line 58, in load
    return self.load_wsgiapp()
           ^^^^^^^^^^^^^^^^^^^
  File "/usr/local/lib/python3.11/site-packages/gunicorn/app/wsgiapp.py", line 48, in load_wsgiapp
    return util.import_app(self.app_uri)
           ^^^^^^^^^^^^^^^^^^^^^^^^^^^^^
  File "/usr/local/lib/python3.11/site-packages/gunicorn/util.py", line 371, in import_app
    mod = importlib.import_module(module)
          ^^^^^^^^^^^^^^^^^^^^^^^^^^^^^^^
  File "/usr/local/lib/python3.11/importlib/__init__.py", line 126, in import_module
    return _bootstrap._gcd_import(name[level:], package, level)
           ^^^^^^^^^^^^^^^^^^^^^^^^^^^^^^^^^^^^^^^^^^^^^^^^^^^^
  File "<frozen importlib._bootstrap>", line 1204, in _gcd_import
  File "<frozen importlib._bootstrap>", line 1176, in _find_and_load
  File "<frozen importlib._bootstrap>", line 1147, in _find_and_load_unlocked
  File "<frozen importlib._bootstrap>", line 690, in _load_unlocked
  File "<frozen importlib._bootstrap_external>", line 936, in exec_module
  File "<frozen importlib._bootstrap_external>", line 1074, in get_code
  File "<frozen importlib._bootstrap_external>", line 1004, in source_to_code
  File "<frozen importlib._bootstrap>", line 241, in _call_with_frames_removed
  File "/app/gongle-web/app.py", line 15
    app.config['SQLALCHEMY_DATABASE_URI'] = os.getenv('DATABASE_URL')'sqlite:////tmp/gongle.db'
                                                                     ^^^^^^^^^^^^^^^^^^^^^^^^^^
SyntaxError: invalid syntax
[2025-05-27 13:25:01 +0000] [22] [INFO] Worker exiting (pid: 22)
[2025-05-27 13:25:01 +0000] [24] [INFO] Booting worker with pid: 24
[2025-05-27 13:25:01 +0000] [23] [ERROR] Exception in worker process
Traceback (most recent call last):
  File "/usr/local/lib/python3.11/site-packages/gunicorn/arbiter.py", line 609, in spawn_worker
    worker.init_process()
  File "/usr/local/lib/python3.11/site-packages/gunicorn/workers/ggevent.py", line 147, in init_process
    super().init_process()
  File "/usr/local/lib/python3.11/site-packages/gunicorn/workers/base.py", line 134, in init_process
    self.load_wsgi()
  File "/usr/local/lib/python3.11/site-packages/gunicorn/workers/base.py", line 146, in load_wsgi
    self.wsgi = self.app.wsgi()
                ^^^^^^^^^^^^^^^
  File "/usr/local/lib/python3.11/site-packages/gunicorn/app/base.py", line 67, in wsgi
    self.callable = self.load()
                    ^^^^^^^^^^^
  File "/usr/local/lib/python3.11/site-packages/gunicorn/app/wsgiapp.py", line 58, in load
    return self.load_wsgiapp()
           ^^^^^^^^^^^^^^^^^^^
  File "/usr/local/lib/python3.11/site-packages/gunicorn/app/wsgiapp.py", line 48, in load_wsgiapp
    return util.import_app(self.app_uri)
           ^^^^^^^^^^^^^^^^^^^^^^^^^^^^^
  File "/usr/local/lib/python3.11/site-packages/gunicorn/util.py", line 371, in import_app
    mod = importlib.import_module(module)
          ^^^^^^^^^^^^^^^^^^^^^^^^^^^^^^^
  File "/usr/local/lib/python3.11/importlib/__init__.py", line 126, in import_module
    return _bootstrap._gcd_import(name[level:], package, level)
           ^^^^^^^^^^^^^^^^^^^^^^^^^^^^^^^^^^^^^^^^^^^^^^^^^^^^
  File "<frozen importlib._bootstrap>", line 1204, in _gcd_import
  File "<frozen importlib._bootstrap>", line 1176, in _find_and_load
  File "<frozen importlib._bootstrap>", line 1147, in _find_and_load_unlocked
  File "<frozen importlib._bootstrap>", line 690, in _load_unlocked
  File "<frozen importlib._bootstrap_external>", line 936, in exec_module
  File "<frozen importlib._bootstrap_external>", line 1074, in get_code
  File "<frozen importlib._bootstrap_external>", line 1004, in source_to_code
  File "<frozen importlib._bootstrap>", line 241, in _call_with_frames_removed
  File "/app/gongle-web/app.py", line 15
    app.config['SQLALCHEMY_DATABASE_URI'] = os.getenv('DATABASE_URL')'sqlite:////tmp/gongle.db'
                                                                     ^^^^^^^^^^^^^^^^^^^^^^^^^^
SyntaxError: invalid syntax
[2025-05-27 13:25:01 +0000] [23] [INFO] Worker exiting (pid: 23)
[2025-05-27 13:25:01 +0000] [8] [ERROR] Worker (pid:22) exited with code 3
[2025-05-27 13:25:01 +0000] [8] [ERROR] Worker (pid:23) was sent SIGTERM!
[2025-05-27 13:25:01 +0000] [24] [ERROR] Exception in worker process
Traceback (most recent call last):
  File "/usr/local/lib/python3.11/site-packages/gunicorn/arbiter.py", line 609, in spawn_worker
    worker.init_process()
  File "/usr/local/lib/python3.11/site-packages/gunicorn/workers/ggevent.py", line 147, in init_process
    super().init_process()
  File "/usr/local/lib/python3.11/site-packages/gunicorn/workers/base.py", line 134, in init_process
    self.load_wsgi()
  File "/usr/local/lib/python3.11/site-packages/gunicorn/workers/base.py", line 146, in load_wsgi
    self.wsgi = self.app.wsgi()
                ^^^^^^^^^^^^^^^
  File "/usr/local/lib/python3.11/site-packages/gunicorn/app/base.py", line 67, in wsgi
    self.callable = self.load()
                    ^^^^^^^^^^^
  File "/usr/local/lib/python3.11/site-packages/gunicorn/app/wsgiapp.py", line 58, in load
    return self.load_wsgiapp()
           ^^^^^^^^^^^^^^^^^^^
  File "/usr/local/lib/python3.11/site-packages/gunicorn/app/wsgiapp.py", line 48, in load_wsgiapp
    return util.import_app(self.app_uri)
           ^^^^^^^^^^^^^^^^^^^^^^^^^^^^^
  File "/usr/local/lib/python3.11/site-packages/gunicorn/util.py", line 371, in import_app
    mod = importlib.import_module(module)
          ^^^^^^^^^^^^^^^^^^^^^^^^^^^^^^^
  File "/usr/local/lib/python3.11/importlib/__init__.py", line 126, in import_module
    return _bootstrap._gcd_import(name[level:], package, level)
           ^^^^^^^^^^^^^^^^^^^^^^^^^^^^^^^^^^^^^^^^^^^^^^^^^^^^
  File "<frozen importlib._bootstrap>", line 1204, in _gcd_import
  File "<frozen importlib._bootstrap>", line 1176, in _find_and_load
  File "<frozen importlib._bootstrap>", line 1147, in _find_and_load_unlocked
  File "<frozen importlib._bootstrap>", line 690, in _load_unlocked
  File "<frozen importlib._bootstrap_external>", line 936, in exec_module
  File "<frozen importlib._bootstrap_external>", line 1074, in get_code
  File "<frozen importlib._bootstrap_external>", line 1004, in source_to_code
  File "<frozen importlib._bootstrap>", line 241, in _call_with_frames_removed
  File "/app/gongle-web/app.py", line 15
    app.config['SQLALCHEMY_DATABASE_URI'] = os.getenv('DATABASE_URL')'sqlite:////tmp/gongle.db'
                                                                     ^^^^^^^^^^^^^^^^^^^^^^^^^^
SyntaxError: invalid syntax
[2025-05-27 13:25:01 +0000] [24] [INFO] Worker exiting (pid: 24)
[2025-05-27 13:25:01 +0000] [8] [ERROR] Worker (pid:24) exited with code 3
Traceback (most recent call last):
  File "/usr/local/lib/python3.11/site-packages/gunicorn/arbiter.py", line 202, in run
    self.manage_workers()
  File "/usr/local/lib/python3.11/site-packages/gunicorn/arbiter.py", line 571, in manage_workers
    self.spawn_workers()
  File "/usr/local/lib/python3.11/site-packages/gunicorn/arbiter.py", line 643, in spawn_workers
    time.sleep(0.1 * random.random())
  File "/usr/local/lib/python3.11/site-packages/gunicorn/arbiter.py", line 242, in handle_chld
    self.reap_workers()
  File "/usr/local/lib/python3.11/site-packages/gunicorn/arbiter.py", line 530, in reap_workers
    raise HaltServer(reason, self.WORKER_BOOT_ERROR)
gunicorn.errors.HaltServer: <HaltServer 'Worker failed to boot.' 3>

During handling of the above exception, another exception occurred:

Traceback (most recent call last):
  File "/usr/local/bin/gunicorn", line 8, in <module>
    sys.exit(run())
             ^^^^^
  File "/usr/local/lib/python3.11/site-packages/gunicorn/app/wsgiapp.py", line 67, in run
    WSGIApplication("%(prog)s [OPTIONS] [APP_MODULE]").run()
  File "/usr/local/lib/python3.11/site-packages/gunicorn/app/base.py", line 236, in run
    super().run()
  File "/usr/local/lib/python3.11/site-packages/gunicorn/app/base.py", line 72, in run
    Arbiter(self).run()
  File "/usr/local/lib/python3.11/site-packages/gunicorn/arbiter.py", line 229, in run
    self.halt(reason=inst.reason, exit_status=inst.exit_status)
  File "/usr/local/lib/python3.11/site-packages/gunicorn/arbiter.py", line 342, in halt
    self.stop()
  File "/usr/local/lib/python3.11/site-packages/gunicorn/arbiter.py", line 396, in stop
    time.sleep(0.1)
  File "/usr/local/lib/python3.11/site-packages/gunicorn/arbiter.py", line 242, in handle_chld
    self.reap_workers()
  File "/usr/local/lib/python3.11/site-packages/gunicorn/arbiter.py", line 530, in reap_workers
    raise HaltServer(reason, self.WORKER_BOOT_ERROR)
gunicorn.errors.HaltServer: <HaltServer 'Worker failed to boot.' 3>
[2025-05-27 13:25:02 +0000] [25] [INFO] Starting gunicorn 21.2.0
[2025-05-27 13:25:02 +0000] [25] [INFO] Listening at: http://127.0.0.1:5000 (25)
[2025-05-27 13:25:02 +0000] [25] [INFO] Using worker: gevent
[2025-05-27 13:25:02 +0000] [26] [INFO] Booting worker with pid: 26
[2025-05-27 13:25:02 +0000] [27] [INFO] Booting worker with pid: 27
[2025-05-27 13:25:02 +0000] [26] [ERROR] Exception in worker process
Traceback (most recent call last):
  File "/usr/local/lib/python3.11/site-packages/gunicorn/arbiter.py", line 609, in spawn_worker
    worker.init_process()
  File "/usr/local/lib/python3.11/site-packages/gunicorn/workers/ggevent.py", line 147, in init_process
    super().init_process()
  File "/usr/local/lib/python3.11/site-packages/gunicorn/workers/base.py", line 134, in init_process
    self.load_wsgi()
  File "/usr/local/lib/python3.11/site-packages/gunicorn/workers/base.py", line 146, in load_wsgi
    self.wsgi = self.app.wsgi()
                ^^^^^^^^^^^^^^^
  File "/usr/local/lib/python3.11/site-packages/gunicorn/app/base.py", line 67, in wsgi
    self.callable = self.load()
                    ^^^^^^^^^^^
  File "/usr/local/lib/python3.11/site-packages/gunicorn/app/wsgiapp.py", line 58, in load
    return self.load_wsgiapp()
           ^^^^^^^^^^^^^^^^^^^
  File "/usr/local/lib/python3.11/site-packages/gunicorn/app/wsgiapp.py", line 48, in load_wsgiapp
    return util.import_app(self.app_uri)
           ^^^^^^^^^^^^^^^^^^^^^^^^^^^^^
  File "/usr/local/lib/python3.11/site-packages/gunicorn/util.py", line 371, in import_app
    mod = importlib.import_module(module)
          ^^^^^^^^^^^^^^^^^^^^^^^^^^^^^^^
  File "/usr/local/lib/python3.11/importlib/__init__.py", line 126, in import_module
    return _bootstrap._gcd_import(name[level:], package, level)
           ^^^^^^^^^^^^^^^^^^^^^^^^^^^^^^^^^^^^^^^^^^^^^^^^^^^^
  File "<frozen importlib._bootstrap>", line 1204, in _gcd_import
  File "<frozen importlib._bootstrap>", line 1176, in _find_and_load
  File "<frozen importlib._bootstrap>", line 1147, in _find_and_load_unlocked
  File "<frozen importlib._bootstrap>", line 690, in _load_unlocked
  File "<frozen importlib._bootstrap_external>", line 936, in exec_module
  File "<frozen importlib._bootstrap_external>", line 1074, in get_code
  File "<frozen importlib._bootstrap_external>", line 1004, in source_to_code
  File "<frozen importlib._bootstrap>", line 241, in _call_with_frames_removed
  File "/app/gongle-web/app.py", line 15
    app.config['SQLALCHEMY_DATABASE_URI'] = os.getenv('DATABASE_URL')'sqlite:////tmp/gongle.db'
                                                                     ^^^^^^^^^^^^^^^^^^^^^^^^^^
SyntaxError: invalid syntax
[2025-05-27 13:25:02 +0000] [26] [INFO] Worker exiting (pid: 26)
[2025-05-27 13:25:02 +0000] [28] [INFO] Booting worker with pid: 28
[2025-05-27 13:25:02 +0000] [27] [ERROR] Exception in worker process
Traceback (most recent call last):
  File "/usr/local/lib/python3.11/site-packages/gunicorn/arbiter.py", line 609, in spawn_worker
    worker.init_process()
  File "/usr/local/lib/python3.11/site-packages/gunicorn/workers/ggevent.py", line 147, in init_process
    super().init_process()
  File "/usr/local/lib/python3.11/site-packages/gunicorn/workers/base.py", line 134, in init_process
    self.load_wsgi()
  File "/usr/local/lib/python3.11/site-packages/gunicorn/workers/base.py", line 146, in load_wsgi
    self.wsgi = self.app.wsgi()
                ^^^^^^^^^^^^^^^
  File "/usr/local/lib/python3.11/site-packages/gunicorn/app/base.py", line 67, in wsgi
    self.callable = self.load()
                    ^^^^^^^^^^^
  File "/usr/local/lib/python3.11/site-packages/gunicorn/app/wsgiapp.py", line 58, in load
    return self.load_wsgiapp()
           ^^^^^^^^^^^^^^^^^^^
  File "/usr/local/lib/python3.11/site-packages/gunicorn/app/wsgiapp.py", line 48, in load_wsgiapp
    return util.import_app(self.app_uri)
           ^^^^^^^^^^^^^^^^^^^^^^^^^^^^^
  File "/usr/local/lib/python3.11/site-packages/gunicorn/util.py", line 371, in import_app
    mod = importlib.import_module(module)
          ^^^^^^^^^^^^^^^^^^^^^^^^^^^^^^^
  File "/usr/local/lib/python3.11/importlib/__init__.py", line 126, in import_module
    return _bootstrap._gcd_import(name[level:], package, level)
           ^^^^^^^^^^^^^^^^^^^^^^^^^^^^^^^^^^^^^^^^^^^^^^^^^^^^
  File "<frozen importlib._bootstrap>", line 1204, in _gcd_import
  File "<frozen importlib._bootstrap>", line 1176, in _find_and_load
  File "<frozen importlib._bootstrap>", line 1147, in _find_and_load_unlocked
  File "<frozen importlib._bootstrap>", line 690, in _load_unlocked
  File "<frozen importlib._bootstrap_external>", line 936, in exec_module
  File "<frozen importlib._bootstrap_external>", line 1074, in get_code
  File "<frozen importlib._bootstrap_external>", line 1004, in source_to_code
  File "<frozen importlib._bootstrap>", line 241, in _call_with_frames_removed
  File "/app/gongle-web/app.py", line 15
    app.config['SQLALCHEMY_DATABASE_URI'] = os.getenv('DATABASE_URL')'sqlite:////tmp/gongle.db'
                                                                     ^^^^^^^^^^^^^^^^^^^^^^^^^^
SyntaxError: invalid syntax
[2025-05-27 13:25:02 +0000] [27] [INFO] Worker exiting (pid: 27)
[2025-05-27 13:25:02 +0000] [25] [ERROR] Worker (pid:26) exited with code 3
[2025-05-27 13:25:02 +0000] [25] [ERROR] Worker (pid:27) was sent SIGTERM!
[2025-05-27 13:25:02 +0000] [28] [ERROR] Exception in worker process
Traceback (most recent call last):
  File "/usr/local/lib/python3.11/site-packages/gunicorn/arbiter.py", line 609, in spawn_worker
    worker.init_process()
  File "/usr/local/lib/python3.11/site-packages/gunicorn/workers/ggevent.py", line 147, in init_process
    super().init_process()
  File "/usr/local/lib/python3.11/site-packages/gunicorn/workers/base.py", line 134, in init_process
    self.load_wsgi()
  File "/usr/local/lib/python3.11/site-packages/gunicorn/workers/base.py", line 146, in load_wsgi
    self.wsgi = self.app.wsgi()
                ^^^^^^^^^^^^^^^
  File "/usr/local/lib/python3.11/site-packages/gunicorn/app/base.py", line 67, in wsgi
    self.callable = self.load()
                    ^^^^^^^^^^^
  File "/usr/local/lib/python3.11/site-packages/gunicorn/app/wsgiapp.py", line 58, in load
    return self.load_wsgiapp()
           ^^^^^^^^^^^^^^^^^^^
  File "/usr/local/lib/python3.11/site-packages/gunicorn/app/wsgiapp.py", line 48, in load_wsgiapp
    return util.import_app(self.app_uri)
           ^^^^^^^^^^^^^^^^^^^^^^^^^^^^^
  File "/usr/local/lib/python3.11/site-packages/gunicorn/util.py", line 371, in import_app
    mod = importlib.import_module(module)
          ^^^^^^^^^^^^^^^^^^^^^^^^^^^^^^^
  File "/usr/local/lib/python3.11/importlib/__init__.py", line 126, in import_module
    return _bootstrap._gcd_import(name[level:], package, level)
           ^^^^^^^^^^^^^^^^^^^^^^^^^^^^^^^^^^^^^^^^^^^^^^^^^^^^
  File "<frozen importlib._bootstrap>", line 1204, in _gcd_import
  File "<frozen importlib._bootstrap>", line 1176, in _find_and_load
  File "<frozen importlib._bootstrap>", line 1147, in _find_and_load_unlocked
  File "<frozen importlib._bootstrap>", line 690, in _load_unlocked
  File "<frozen importlib._bootstrap_external>", line 936, in exec_module
  File "<frozen importlib._bootstrap_external>", line 1074, in get_code
  File "<frozen importlib._bootstrap_external>", line 1004, in source_to_code
  File "<frozen importlib._bootstrap>", line 241, in _call_with_frames_removed
  File "/app/gongle-web/app.py", line 15
    app.config['SQLALCHEMY_DATABASE_URI'] = os.getenv('DATABASE_URL')'sqlite:////tmp/gongle.db'
                                                                     ^^^^^^^^^^^^^^^^^^^^^^^^^^
SyntaxError: invalid syntax
[2025-05-27 13:25:02 +0000] [28] [INFO] Worker exiting (pid: 28)
[2025-05-27 13:25:02 +0000] [25] [ERROR] Worker (pid:28) exited with code 3
Traceback (most recent call last):
  File "/usr/local/lib/python3.11/site-packages/gunicorn/arbiter.py", line 202, in run
    self.manage_workers()
  File "/usr/local/lib/python3.11/site-packages/gunicorn/arbiter.py", line 571, in manage_workers
    self.spawn_workers()
  File "/usr/local/lib/python3.11/site-packages/gunicorn/arbiter.py", line 643, in spawn_workers
    time.sleep(0.1 * random.random())
  File "/usr/local/lib/python3.11/site-packages/gunicorn/arbiter.py", line 242, in handle_chld
    self.reap_workers()
  File "/usr/local/lib/python3.11/site-packages/gunicorn/arbiter.py", line 530, in reap_workers
    raise HaltServer(reason, self.WORKER_BOOT_ERROR)
gunicorn.errors.HaltServer: <HaltServer 'Worker failed to boot.' 3>

During handling of the above exception, another exception occurred:

Traceback (most recent call last):
  File "/usr/local/bin/gunicorn", line 8, in <module>
    sys.exit(run())
             ^^^^^
  File "/usr/local/lib/python3.11/site-packages/gunicorn/app/wsgiapp.py", line 67, in run
    WSGIApplication("%(prog)s [OPTIONS] [APP_MODULE]").run()
  File "/usr/local/lib/python3.11/site-packages/gunicorn/app/base.py", line 236, in run
    super().run()
  File "/usr/local/lib/python3.11/site-packages/gunicorn/app/base.py", line 72, in run
    Arbiter(self).run()
  File "/usr/local/lib/python3.11/site-packages/gunicorn/arbiter.py", line 229, in run
    self.halt(reason=inst.reason, exit_status=inst.exit_status)
  File "/usr/local/lib/python3.11/site-packages/gunicorn/arbiter.py", line 342, in halt
    self.stop()
  File "/usr/local/lib/python3.11/site-packages/gunicorn/arbiter.py", line 396, in stop
    time.sleep(0.1)
  File "/usr/local/lib/python3.11/site-packages/gunicorn/arbiter.py", line 242, in handle_chld
    self.reap_workers()
  File "/usr/local/lib/python3.11/site-packages/gunicorn/arbiter.py", line 530, in reap_workers
    raise HaltServer(reason, self.WORKER_BOOT_ERROR)
gunicorn.errors.HaltServer: <HaltServer 'Worker failed to boot.' 3>
[2025-05-27 13:25:04 +0000] [29] [INFO] Starting gunicorn 21.2.0
[2025-05-27 13:25:04 +0000] [29] [INFO] Listening at: http://127.0.0.1:5000 (29)
[2025-05-27 13:25:04 +0000] [29] [INFO] Using worker: gevent
[2025-05-27 13:25:04 +0000] [30] [INFO] Booting worker with pid: 30
[2025-05-27 13:25:04 +0000] [30] [ERROR] Exception in worker process
Traceback (most recent call last):
  File "/usr/local/lib/python3.11/site-packages/gunicorn/arbiter.py", line 609, in spawn_worker
    worker.init_process()
  File "/usr/local/lib/python3.11/site-packages/gunicorn/workers/ggevent.py", line 147, in init_process
    super().init_process()
  File "/usr/local/lib/python3.11/site-packages/gunicorn/workers/base.py", line 134, in init_process
    self.load_wsgi()
  File "/usr/local/lib/python3.11/site-packages/gunicorn/workers/base.py", line 146, in load_wsgi
    self.wsgi = self.app.wsgi()
                ^^^^^^^^^^^^^^^
  File "/usr/local/lib/python3.11/site-packages/gunicorn/app/base.py", line 67, in wsgi
    self.callable = self.load()
                    ^^^^^^^^^^^
  File "/usr/local/lib/python3.11/site-packages/gunicorn/app/wsgiapp.py", line 58, in load
    return self.load_wsgiapp()
           ^^^^^^^^^^^^^^^^^^^
  File "/usr/local/lib/python3.11/site-packages/gunicorn/app/wsgiapp.py", line 48, in load_wsgiapp
    return util.import_app(self.app_uri)
           ^^^^^^^^^^^^^^^^^^^^^^^^^^^^^
  File "/usr/local/lib/python3.11/site-packages/gunicorn/util.py", line 371, in import_app
    mod = importlib.import_module(module)
          ^^^^^^^^^^^^^^^^^^^^^^^^^^^^^^^
  File "/usr/local/lib/python3.11/importlib/__init__.py", line 126, in import_module
    return _bootstrap._gcd_import(name[level:], package, level)
           ^^^^^^^^^^^^^^^^^^^^^^^^^^^^^^^^^^^^^^^^^^^^^^^^^^^^
  File "<frozen importlib._bootstrap>", line 1204, in _gcd_import
  File "<frozen importlib._bootstrap>", line 1176, in _find_and_load
  File "<frozen importlib._bootstrap>", line 1147, in _find_and_load_unlocked
  File "<frozen importlib._bootstrap>", line 690, in _load_unlocked
  File "<frozen importlib._bootstrap_external>", line 936, in exec_module
  File "<frozen importlib._bootstrap_external>", line 1074, in get_code
  File "<frozen importlib._bootstrap_external>", line 1004, in source_to_code
  File "<frozen importlib._bootstrap>", line 241, in _call_with_frames_removed
  File "/app/gongle-web/app.py", line 15
    app.config['SQLALCHEMY_DATABASE_URI'] = os.getenv('DATABASE_URL')'sqlite:////tmp/gongle.db'
                                                                     ^^^^^^^^^^^^^^^^^^^^^^^^^^
SyntaxError: invalid syntax
[2025-05-27 13:25:04 +0000] [30] [INFO] Worker exiting (pid: 30)
[2025-05-27 13:25:04 +0000] [31] [INFO] Booting worker with pid: 31
[2025-05-27 13:25:04 +0000] [29] [ERROR] Worker (pid:30) exited with code 3
[2025-05-27 13:25:04 +0000] [31] [ERROR] Exception in worker process
Traceback (most recent call last):
  File "/usr/local/lib/python3.11/site-packages/gunicorn/arbiter.py", line 609, in spawn_worker
    worker.init_process()
  File "/usr/local/lib/python3.11/site-packages/gunicorn/workers/ggevent.py", line 147, in init_process
    super().init_process()
  File "/usr/local/lib/python3.11/site-packages/gunicorn/workers/base.py", line 134, in init_process
    self.load_wsgi()
  File "/usr/local/lib/python3.11/site-packages/gunicorn/workers/base.py", line 146, in load_wsgi
    self.wsgi = self.app.wsgi()
                ^^^^^^^^^^^^^^^
  File "/usr/local/lib/python3.11/site-packages/gunicorn/app/base.py", line 67, in wsgi
    self.callable = self.load()
                    ^^^^^^^^^^^
  File "/usr/local/lib/python3.11/site-packages/gunicorn/app/wsgiapp.py", line 58, in load
    return self.load_wsgiapp()
           ^^^^^^^^^^^^^^^^^^^
  File "/usr/local/lib/python3.11/site-packages/gunicorn/app/wsgiapp.py", line 48, in load_wsgiapp
    return util.import_app(self.app_uri)
           ^^^^^^^^^^^^^^^^^^^^^^^^^^^^^
  File "/usr/local/lib/python3.11/site-packages/gunicorn/util.py", line 371, in import_app
    mod = importlib.import_module(module)
          ^^^^^^^^^^^^^^^^^^^^^^^^^^^^^^^
  File "/usr/local/lib/python3.11/importlib/__init__.py", line 126, in import_module
    return _bootstrap._gcd_import(name[level:], package, level)
           ^^^^^^^^^^^^^^^^^^^^^^^^^^^^^^^^^^^^^^^^^^^^^^^^^^^^
  File "<frozen importlib._bootstrap>", line 1204, in _gcd_import
  File "<frozen importlib._bootstrap>", line 1176, in _find_and_load
  File "<frozen importlib._bootstrap>", line 1147, in _find_and_load_unlocked
  File "<frozen importlib._bootstrap>", line 690, in _load_unlocked
  File "<frozen importlib._bootstrap_external>", line 936, in exec_module
  File "<frozen importlib._bootstrap_external>", line 1074, in get_code
  File "<frozen importlib._bootstrap_external>", line 1004, in source_to_code
  File "<frozen importlib._bootstrap>", line 241, in _call_with_frames_removed
  File "/app/gongle-web/app.py", line 15
    app.config['SQLALCHEMY_DATABASE_URI'] = os.getenv('DATABASE_URL')'sqlite:////tmp/gongle.db'
                                                                     ^^^^^^^^^^^^^^^^^^^^^^^^^^
SyntaxError: invalid syntax
[2025-05-27 13:25:04 +0000] [31] [INFO] Worker exiting (pid: 31)
[2025-05-27 13:25:04 +0000] [29] [ERROR] Worker (pid:31) exited with code 3
Traceback (most recent call last):
  File "/usr/local/lib/python3.11/site-packages/gunicorn/arbiter.py", line 202, in run
    self.manage_workers()
  File "/usr/local/lib/python3.11/site-packages/gunicorn/arbiter.py", line 571, in manage_workers
    self.spawn_workers()
  File "/usr/local/lib/python3.11/site-packages/gunicorn/arbiter.py", line 643, in spawn_workers
    time.sleep(0.1 * random.random())
  File "/usr/local/lib/python3.11/site-packages/gunicorn/arbiter.py", line 242, in handle_chld
    self.reap_workers()
  File "/usr/local/lib/python3.11/site-packages/gunicorn/arbiter.py", line 530, in reap_workers
    raise HaltServer(reason, self.WORKER_BOOT_ERROR)
gunicorn.errors.HaltServer: <HaltServer 'Worker failed to boot.' 3>

During handling of the above exception, another exception occurred:

Traceback (most recent call last):
  File "/usr/local/bin/gunicorn", line 8, in <module>
    sys.exit(run())
             ^^^^^
  File "/usr/local/lib/python3.11/site-packages/gunicorn/app/wsgiapp.py", line 67, in run
    WSGIApplication("%(prog)s [OPTIONS] [APP_MODULE]").run()
  File "/usr/local/lib/python3.11/site-packages/gunicorn/app/base.py", line 236, in run
    super().run()
  File "/usr/local/lib/python3.11/site-packages/gunicorn/app/base.py", line 72, in run
    Arbiter(self).run()
  File "/usr/local/lib/python3.11/site-packages/gunicorn/arbiter.py", line 229, in run
    self.halt(reason=inst.reason, exit_status=inst.exit_status)
  File "/usr/local/lib/python3.11/site-packages/gunicorn/arbiter.py", line 342, in halt
    self.stop()
  File "/usr/local/lib/python3.11/site-packages/gunicorn/arbiter.py", line 396, in stop
    time.sleep(0.1)
  File "/usr/local/lib/python3.11/site-packages/gunicorn/arbiter.py", line 242, in handle_chld
    self.reap_workers()
  File "/usr/local/lib/python3.11/site-packages/gunicorn/arbiter.py", line 530, in reap_workers
    raise HaltServer(reason, self.WORKER_BOOT_ERROR)
gunicorn.errors.HaltServer: <HaltServer 'Worker failed to boot.' 3>
[2025-05-27 13:25:08 +0000] [32] [INFO] Starting gunicorn 21.2.0
[2025-05-27 13:25:08 +0000] [32] [INFO] Listening at: http://127.0.0.1:5000 (32)
[2025-05-27 13:25:08 +0000] [32] [INFO] Using worker: gevent
[2025-05-27 13:25:08 +0000] [33] [INFO] Booting worker with pid: 33
[2025-05-27 13:25:08 +0000] [34] [INFO] Booting worker with pid: 34
[2025-05-27 13:25:08 +0000] [35] [INFO] Booting worker with pid: 35
[2025-05-27 13:25:08 +0000] [36] [INFO] Booting worker with pid: 36
[2025-05-27 13:25:08 +0000] [33] [ERROR] Exception in worker process
Traceback (most recent call last):
  File "/usr/local/lib/python3.11/site-packages/gunicorn/arbiter.py", line 609, in spawn_worker
    worker.init_process()
  File "/usr/local/lib/python3.11/site-packages/gunicorn/workers/ggevent.py", line 147, in init_process
    super().init_process()
  File "/usr/local/lib/python3.11/site-packages/gunicorn/workers/base.py", line 134, in init_process
    self.load_wsgi()
  File "/usr/local/lib/python3.11/site-packages/gunicorn/workers/base.py", line 146, in load_wsgi
    self.wsgi = self.app.wsgi()
                ^^^^^^^^^^^^^^^
  File "/usr/local/lib/python3.11/site-packages/gunicorn/app/base.py", line 67, in wsgi
    self.callable = self.load()
                    ^^^^^^^^^^^
  File "/usr/local/lib/python3.11/site-packages/gunicorn/app/wsgiapp.py", line 58, in load
    return self.load_wsgiapp()
           ^^^^^^^^^^^^^^^^^^^
  File "/usr/local/lib/python3.11/site-packages/gunicorn/app/wsgiapp.py", line 48, in load_wsgiapp
    return util.import_app(self.app_uri)
           ^^^^^^^^^^^^^^^^^^^^^^^^^^^^^
  File "/usr/local/lib/python3.11/site-packages/gunicorn/util.py", line 371, in import_app
    mod = importlib.import_module(module)
          ^^^^^^^^^^^^^^^^^^^^^^^^^^^^^^^
  File "/usr/local/lib/python3.11/importlib/__init__.py", line 126, in import_module
    return _bootstrap._gcd_import(name[level:], package, level)
           ^^^^^^^^^^^^^^^^^^^^^^^^^^^^^^^^^^^^^^^^^^^^^^^^^^^^
  File "<frozen importlib._bootstrap>", line 1204, in _gcd_import
  File "<frozen importlib._bootstrap>", line 1176, in _find_and_load
  File "<frozen importlib._bootstrap>", line 1147, in _find_and_load_unlocked
  File "<frozen importlib._bootstrap>", line 690, in _load_unlocked
  File "<frozen importlib._bootstrap_external>", line 936, in exec_module
  File "<frozen importlib._bootstrap_external>", line 1074, in get_code
  File "<frozen importlib._bootstrap_external>", line 1004, in source_to_code
  File "<frozen importlib._bootstrap>", line 241, in _call_with_frames_removed
  File "/app/gongle-web/app.py", line 15
    app.config['SQLALCHEMY_DATABASE_URI'] = os.getenv('DATABASE_URL')'sqlite:////tmp/gongle.db'
                                                                     ^^^^^^^^^^^^^^^^^^^^^^^^^^
SyntaxError: invalid syntax
[2025-05-27 13:25:08 +0000] [33] [INFO] Worker exiting (pid: 33)
[2025-05-27 13:25:08 +0000] [34] [ERROR] Exception in worker process
Traceback (most recent call last):
  File "/usr/local/lib/python3.11/site-packages/gunicorn/arbiter.py", line 609, in spawn_worker
    worker.init_process()
  File "/usr/local/lib/python3.11/site-packages/gunicorn/workers/ggevent.py", line 147, in init_process
    super().init_process()
  File "/usr/local/lib/python3.11/site-packages/gunicorn/workers/base.py", line 134, in init_process
    self.load_wsgi()
  File "/usr/local/lib/python3.11/site-packages/gunicorn/workers/base.py", line 146, in load_wsgi
    self.wsgi = self.app.wsgi()
                ^^^^^^^^^^^^^^^
  File "/usr/local/lib/python3.11/site-packages/gunicorn/app/base.py", line 67, in wsgi
    self.callable = self.load()
                    ^^^^^^^^^^^
  File "/usr/local/lib/python3.11/site-packages/gunicorn/app/wsgiapp.py", line 58, in load
    return self.load_wsgiapp()
           ^^^^^^^^^^^^^^^^^^^
  File "/usr/local/lib/python3.11/site-packages/gunicorn/app/wsgiapp.py", line 48, in load_wsgiapp
    return util.import_app(self.app_uri)
           ^^^^^^^^^^^^^^^^^^^^^^^^^^^^^
  File "/usr/local/lib/python3.11/site-packages/gunicorn/util.py", line 371, in import_app
    mod = importlib.import_module(module)
          ^^^^^^^^^^^^^^^^^^^^^^^^^^^^^^^
  File "/usr/local/lib/python3.11/importlib/__init__.py", line 126, in import_module
    return _bootstrap._gcd_import(name[level:], package, level)
           ^^^^^^^^^^^^^^^^^^^^^^^^^^^^^^^^^^^^^^^^^^^^^^^^^^^^
  File "<frozen importlib._bootstrap>", line 1204, in _gcd_import
  File "<frozen importlib._bootstrap>", line 1176, in _find_and_load
  File "<frozen importlib._bootstrap>", line 1147, in _find_and_load_unlocked
  File "<frozen importlib._bootstrap>", line 690, in _load_unlocked
  File "<frozen importlib._bootstrap_external>", line 936, in exec_module
  File "<frozen importlib._bootstrap_external>", line 1074, in get_code
  File "<frozen importlib._bootstrap_external>", line 1004, in source_to_code
  File "<frozen importlib._bootstrap>", line 241, in _call_with_frames_removed
  File "/app/gongle-web/app.py", line 15
    app.config['SQLALCHEMY_DATABASE_URI'] = os.getenv('DATABASE_URL')'sqlite:////tmp/gongle.db'
                                                                     ^^^^^^^^^^^^^^^^^^^^^^^^^^
SyntaxError: invalid syntax
[2025-05-27 13:25:08 +0000] [34] [INFO] Worker exiting (pid: 34)
[2025-05-27 13:25:08 +0000] [35] [ERROR] Exception in worker process
Traceback (most recent call last):
  File "/usr/local/lib/python3.11/site-packages/gunicorn/arbiter.py", line 609, in spawn_worker
    worker.init_process()
  File "/usr/local/lib/python3.11/site-packages/gunicorn/workers/ggevent.py", line 147, in init_process
    super().init_process()
  File "/usr/local/lib/python3.11/site-packages/gunicorn/workers/base.py", line 134, in init_process
    self.load_wsgi()
  File "/usr/local/lib/python3.11/site-packages/gunicorn/workers/base.py", line 146, in load_wsgi
    self.wsgi = self.app.wsgi()
                ^^^^^^^^^^^^^^^
  File "/usr/local/lib/python3.11/site-packages/gunicorn/app/base.py", line 67, in wsgi
    self.callable = self.load()
                    ^^^^^^^^^^^
  File "/usr/local/lib/python3.11/site-packages/gunicorn/app/wsgiapp.py", line 58, in load
    return self.load_wsgiapp()
           ^^^^^^^^^^^^^^^^^^^
  File "/usr/local/lib/python3.11/site-packages/gunicorn/app/wsgiapp.py", line 48, in load_wsgiapp
    return util.import_app(self.app_uri)
           ^^^^^^^^^^^^^^^^^^^^^^^^^^^^^
  File "/usr/local/lib/python3.11/site-packages/gunicorn/util.py", line 371, in import_app
    mod = importlib.import_module(module)
          ^^^^^^^^^^^^^^^^^^^^^^^^^^^^^^^
  File "/usr/local/lib/python3.11/importlib/__init__.py", line 126, in import_module
    return _bootstrap._gcd_import(name[level:], package, level)
           ^^^^^^^^^^^^^^^^^^^^^^^^^^^^^^^^^^^^^^^^^^^^^^^^^^^^
  File "<frozen importlib._bootstrap>", line 1204, in _gcd_import
  File "<frozen importlib._bootstrap>", line 1176, in _find_and_load
  File "<frozen importlib._bootstrap>", line 1147, in _find_and_load_unlocked
  File "<frozen importlib._bootstrap>", line 690, in _load_unlocked
  File "<frozen importlib._bootstrap_external>", line 936, in exec_module
  File "<frozen importlib._bootstrap_external>", line 1074, in get_code
  File "<frozen importlib._bootstrap_external>", line 1004, in source_to_code
  File "<frozen importlib._bootstrap>", line 241, in _call_with_frames_removed
  File "/app/gongle-web/app.py", line 15
    app.config['SQLALCHEMY_DATABASE_URI'] = os.getenv('DATABASE_URL')'sqlite:////tmp/gongle.db'
                                                                     ^^^^^^^^^^^^^^^^^^^^^^^^^^
SyntaxError: invalid syntax
[2025-05-27 13:25:08 +0000] [35] [INFO] Worker exiting (pid: 35)
[2025-05-27 13:25:08 +0000] [36] [ERROR] Exception in worker process
Traceback (most recent call last):
  File "/usr/local/lib/python3.11/site-packages/gunicorn/arbiter.py", line 609, in spawn_worker
    worker.init_process()
  File "/usr/local/lib/python3.11/site-packages/gunicorn/workers/ggevent.py", line 147, in init_process
    super().init_process()
  File "/usr/local/lib/python3.11/site-packages/gunicorn/workers/base.py", line 134, in init_process
    self.load_wsgi()
  File "/usr/local/lib/python3.11/site-packages/gunicorn/workers/base.py", line 146, in load_wsgi
    self.wsgi = self.app.wsgi()
                ^^^^^^^^^^^^^^^
  File "/usr/local/lib/python3.11/site-packages/gunicorn/app/base.py", line 67, in wsgi
    self.callable = self.load()
                    ^^^^^^^^^^^
  File "/usr/local/lib/python3.11/site-packages/gunicorn/app/wsgiapp.py", line 58, in load
    return self.load_wsgiapp()
           ^^^^^^^^^^^^^^^^^^^
  File "/usr/local/lib/python3.11/site-packages/gunicorn/app/wsgiapp.py", line 48, in load_wsgiapp
    return util.import_app(self.app_uri)
           ^^^^^^^^^^^^^^^^^^^^^^^^^^^^^
  File "/usr/local/lib/python3.11/site-packages/gunicorn/util.py", line 371, in import_app
    mod = importlib.import_module(module)
          ^^^^^^^^^^^^^^^^^^^^^^^^^^^^^^^
  File "/usr/local/lib/python3.11/importlib/__init__.py", line 126, in import_module
    return _bootstrap._gcd_import(name[level:], package, level)
           ^^^^^^^^^^^^^^^^^^^^^^^^^^^^^^^^^^^^^^^^^^^^^^^^^^^^
  File "<frozen importlib._bootstrap>", line 1204, in _gcd_import
  File "<frozen importlib._bootstrap>", line 1176, in _find_and_load
  File "<frozen importlib._bootstrap>", line 1147, in _find_and_load_unlocked
  File "<frozen importlib._bootstrap>", line 690, in _load_unlocked
  File "<frozen importlib._bootstrap_external>", line 936, in exec_module
  File "<frozen importlib._bootstrap_external>", line 1074, in get_code
  File "<frozen importlib._bootstrap_external>", line 1004, in source_to_code
  File "<frozen importlib._bootstrap>", line 241, in _call_with_frames_removed
  File "/app/gongle-web/app.py", line 15
    app.config['SQLALCHEMY_DATABASE_URI'] = os.getenv('DATABASE_URL')'sqlite:////tmp/gongle.db'
                                                                     ^^^^^^^^^^^^^^^^^^^^^^^^^^
SyntaxError: invalid syntax
[2025-05-27 13:25:08 +0000] [36] [INFO] Worker exiting (pid: 36)
[2025-05-27 13:25:08 +0000] [32] [ERROR] Worker (pid:33) exited with code 3
[2025-05-27 13:25:08 +0000] [32] [ERROR] Worker (pid:34) was sent SIGTERM!
[2025-05-27 13:25:08 +0000] [32] [ERROR] Worker (pid:35) was sent SIGTERM!
[2025-05-27 13:25:08 +0000] [32] [ERROR] Worker (pid:36) was sent SIGTERM!
[2025-05-27 13:25:08 +0000] [32] [ERROR] Shutting down: Master
[2025-05-27 13:25:08 +0000] [32] [ERROR] Reason: Worker failed to boot.
[2025-05-27 13:40:02 +0000] [8] [INFO] Starting gunicorn 21.2.0
[2025-05-27 13:40:02 +0000] [8] [INFO] Listening at: http://127.0.0.1:5000 (8)
[2025-05-27 13:40:02 +0000] [8] [INFO] Using worker: gevent
[2025-05-27 13:40:02 +0000] [22] [INFO] Booting worker with pid: 22
[2025-05-27 13:40:02 +0000] [22] [ERROR] Exception in worker process
Traceback (most recent call last):
  File "/usr/local/lib/python3.11/site-packages/gunicorn/arbiter.py", line 609, in spawn_worker
    worker.init_process()
  File "/usr/local/lib/python3.11/site-packages/gunicorn/workers/ggevent.py", line 147, in init_process
    super().init_process()
  File "/usr/local/lib/python3.11/site-packages/gunicorn/workers/base.py", line 134, in init_process
    self.load_wsgi()
  File "/usr/local/lib/python3.11/site-packages/gunicorn/workers/base.py", line 146, in load_wsgi
    self.wsgi = self.app.wsgi()
                ^^^^^^^^^^^^^^^
  File "/usr/local/lib/python3.11/site-packages/gunicorn/app/base.py", line 67, in wsgi
    self.callable = self.load()
                    ^^^^^^^^^^^
  File "/usr/local/lib/python3.11/site-packages/gunicorn/app/wsgiapp.py", line 58, in load
    return self.load_wsgiapp()
           ^^^^^^^^^^^^^^^^^^^
  File "/usr/local/lib/python3.11/site-packages/gunicorn/app/wsgiapp.py", line 48, in load_wsgiapp
    return util.import_app(self.app_uri)
           ^^^^^^^^^^^^^^^^^^^^^^^^^^^^^
  File "/usr/local/lib/python3.11/site-packages/gunicorn/util.py", line 371, in import_app
    mod = importlib.import_module(module)
          ^^^^^^^^^^^^^^^^^^^^^^^^^^^^^^^
  File "/usr/local/lib/python3.11/importlib/__init__.py", line 126, in import_module
    return _bootstrap._gcd_import(name[level:], package, level)
           ^^^^^^^^^^^^^^^^^^^^^^^^^^^^^^^^^^^^^^^^^^^^^^^^^^^^
  File "<frozen importlib._bootstrap>", line 1204, in _gcd_import
  File "<frozen importlib._bootstrap>", line 1176, in _find_and_load
  File "<frozen importlib._bootstrap>", line 1147, in _find_and_load_unlocked
  File "<frozen importlib._bootstrap>", line 690, in _load_unlocked
  File "<frozen importlib._bootstrap_external>", line 936, in exec_module
  File "<frozen importlib._bootstrap_external>", line 1074, in get_code
  File "<frozen importlib._bootstrap_external>", line 1004, in source_to_code
  File "<frozen importlib._bootstrap>", line 241, in _call_with_frames_removed
  File "/app/gongle-web/app.py", line 15
    app.config['SQLALCHEMY_DATABASE_URI'] = os.getenv('DATABASE_URL')'sqlite:////tmp/gongle.db'
                                                                     ^^^^^^^^^^^^^^^^^^^^^^^^^^
SyntaxError: invalid syntax
[2025-05-27 13:40:02 +0000] [22] [INFO] Worker exiting (pid: 22)
[2025-05-27 13:40:02 +0000] [23] [INFO] Booting worker with pid: 23
[2025-05-27 13:40:02 +0000] [8] [ERROR] Worker (pid:22) exited with code 3
[2025-05-27 13:40:02 +0000] [23] [ERROR] Exception in worker process
Traceback (most recent call last):
  File "/usr/local/lib/python3.11/site-packages/gunicorn/arbiter.py", line 609, in spawn_worker
    worker.init_process()
  File "/usr/local/lib/python3.11/site-packages/gunicorn/workers/ggevent.py", line 147, in init_process
    super().init_process()
  File "/usr/local/lib/python3.11/site-packages/gunicorn/workers/base.py", line 134, in init_process
    self.load_wsgi()
  File "/usr/local/lib/python3.11/site-packages/gunicorn/workers/base.py", line 146, in load_wsgi
    self.wsgi = self.app.wsgi()
                ^^^^^^^^^^^^^^^
  File "/usr/local/lib/python3.11/site-packages/gunicorn/app/base.py", line 67, in wsgi
    self.callable = self.load()
                    ^^^^^^^^^^^
  File "/usr/local/lib/python3.11/site-packages/gunicorn/app/wsgiapp.py", line 58, in load
    return self.load_wsgiapp()
           ^^^^^^^^^^^^^^^^^^^
  File "/usr/local/lib/python3.11/site-packages/gunicorn/app/wsgiapp.py", line 48, in load_wsgiapp
    return util.import_app(self.app_uri)
           ^^^^^^^^^^^^^^^^^^^^^^^^^^^^^
  File "/usr/local/lib/python3.11/site-packages/gunicorn/util.py", line 371, in import_app
    mod = importlib.import_module(module)
          ^^^^^^^^^^^^^^^^^^^^^^^^^^^^^^^
  File "/usr/local/lib/python3.11/importlib/__init__.py", line 126, in import_module
    return _bootstrap._gcd_import(name[level:], package, level)
           ^^^^^^^^^^^^^^^^^^^^^^^^^^^^^^^^^^^^^^^^^^^^^^^^^^^^
  File "<frozen importlib._bootstrap>", line 1204, in _gcd_import
  File "<frozen importlib._bootstrap>", line 1176, in _find_and_load
  File "<frozen importlib._bootstrap>", line 1147, in _find_and_load_unlocked
  File "<frozen importlib._bootstrap>", line 690, in _load_unlocked
  File "<frozen importlib._bootstrap_external>", line 936, in exec_module
  File "<frozen importlib._bootstrap_external>", line 1074, in get_code
  File "<frozen importlib._bootstrap_external>", line 1004, in source_to_code
  File "<frozen importlib._bootstrap>", line 241, in _call_with_frames_removed
  File "/app/gongle-web/app.py", line 15
    app.config['SQLALCHEMY_DATABASE_URI'] = os.getenv('DATABASE_URL')'sqlite:////tmp/gongle.db'
                                                                     ^^^^^^^^^^^^^^^^^^^^^^^^^^
SyntaxError: invalid syntax
[2025-05-27 13:40:02 +0000] [23] [INFO] Worker exiting (pid: 23)
[2025-05-27 13:40:02 +0000] [8] [ERROR] Worker (pid:23) exited with code 3
Traceback (most recent call last):
  File "/usr/local/lib/python3.11/site-packages/gunicorn/arbiter.py", line 202, in run
    self.manage_workers()
  File "/usr/local/lib/python3.11/site-packages/gunicorn/arbiter.py", line 571, in manage_workers
    self.spawn_workers()
  File "/usr/local/lib/python3.11/site-packages/gunicorn/arbiter.py", line 643, in spawn_workers
    time.sleep(0.1 * random.random())
  File "/usr/local/lib/python3.11/site-packages/gunicorn/arbiter.py", line 242, in handle_chld
    self.reap_workers()
  File "/usr/local/lib/python3.11/site-packages/gunicorn/arbiter.py", line 530, in reap_workers
    raise HaltServer(reason, self.WORKER_BOOT_ERROR)
gunicorn.errors.HaltServer: <HaltServer 'Worker failed to boot.' 3>

During handling of the above exception, another exception occurred:

Traceback (most recent call last):
  File "/usr/local/bin/gunicorn", line 8, in <module>
    sys.exit(run())
             ^^^^^
  File "/usr/local/lib/python3.11/site-packages/gunicorn/app/wsgiapp.py", line 67, in run
    WSGIApplication("%(prog)s [OPTIONS] [APP_MODULE]").run()
  File "/usr/local/lib/python3.11/site-packages/gunicorn/app/base.py", line 236, in run
    super().run()
  File "/usr/local/lib/python3.11/site-packages/gunicorn/app/base.py", line 72, in run
    Arbiter(self).run()
  File "/usr/local/lib/python3.11/site-packages/gunicorn/arbiter.py", line 229, in run
    self.halt(reason=inst.reason, exit_status=inst.exit_status)
  File "/usr/local/lib/python3.11/site-packages/gunicorn/arbiter.py", line 342, in halt
    self.stop()
  File "/usr/local/lib/python3.11/site-packages/gunicorn/arbiter.py", line 396, in stop
    time.sleep(0.1)
  File "/usr/local/lib/python3.11/site-packages/gunicorn/arbiter.py", line 242, in handle_chld
    self.reap_workers()
  File "/usr/local/lib/python3.11/site-packages/gunicorn/arbiter.py", line 530, in reap_workers
    raise HaltServer(reason, self.WORKER_BOOT_ERROR)
gunicorn.errors.HaltServer: <HaltServer 'Worker failed to boot.' 3>
[2025-05-27 13:40:03 +0000] [24] [INFO] Starting gunicorn 21.2.0
[2025-05-27 13:40:03 +0000] [24] [INFO] Listening at: http://127.0.0.1:5000 (24)
[2025-05-27 13:40:03 +0000] [24] [INFO] Using worker: gevent
[2025-05-27 13:40:03 +0000] [25] [INFO] Booting worker with pid: 25
[2025-05-27 13:40:03 +0000] [26] [INFO] Booting worker with pid: 26
[2025-05-27 13:40:03 +0000] [25] [ERROR] Exception in worker process
Traceback (most recent call last):
  File "/usr/local/lib/python3.11/site-packages/gunicorn/arbiter.py", line 609, in spawn_worker
    worker.init_process()
  File "/usr/local/lib/python3.11/site-packages/gunicorn/workers/ggevent.py", line 147, in init_process
    super().init_process()
  File "/usr/local/lib/python3.11/site-packages/gunicorn/workers/base.py", line 134, in init_process
    self.load_wsgi()
  File "/usr/local/lib/python3.11/site-packages/gunicorn/workers/base.py", line 146, in load_wsgi
    self.wsgi = self.app.wsgi()
                ^^^^^^^^^^^^^^^
  File "/usr/local/lib/python3.11/site-packages/gunicorn/app/base.py", line 67, in wsgi
    self.callable = self.load()
                    ^^^^^^^^^^^
  File "/usr/local/lib/python3.11/site-packages/gunicorn/app/wsgiapp.py", line 58, in load
    return self.load_wsgiapp()
           ^^^^^^^^^^^^^^^^^^^
  File "/usr/local/lib/python3.11/site-packages/gunicorn/app/wsgiapp.py", line 48, in load_wsgiapp
    return util.import_app(self.app_uri)
           ^^^^^^^^^^^^^^^^^^^^^^^^^^^^^
  File "/usr/local/lib/python3.11/site-packages/gunicorn/util.py", line 371, in import_app
    mod = importlib.import_module(module)
          ^^^^^^^^^^^^^^^^^^^^^^^^^^^^^^^
  File "/usr/local/lib/python3.11/importlib/__init__.py", line 126, in import_module
    return _bootstrap._gcd_import(name[level:], package, level)
           ^^^^^^^^^^^^^^^^^^^^^^^^^^^^^^^^^^^^^^^^^^^^^^^^^^^^
  File "<frozen importlib._bootstrap>", line 1204, in _gcd_import
  File "<frozen importlib._bootstrap>", line 1176, in _find_and_load
  File "<frozen importlib._bootstrap>", line 1147, in _find_and_load_unlocked
  File "<frozen importlib._bootstrap>", line 690, in _load_unlocked
  File "<frozen importlib._bootstrap_external>", line 936, in exec_module
  File "<frozen importlib._bootstrap_external>", line 1074, in get_code
  File "<frozen importlib._bootstrap_external>", line 1004, in source_to_code
  File "<frozen importlib._bootstrap>", line 241, in _call_with_frames_removed
  File "/app/gongle-web/app.py", line 15
    app.config['SQLALCHEMY_DATABASE_URI'] = os.getenv('DATABASE_URL')'sqlite:////tmp/gongle.db'
                                                                     ^^^^^^^^^^^^^^^^^^^^^^^^^^
SyntaxError: invalid syntax
[2025-05-27 13:40:03 +0000] [25] [INFO] Worker exiting (pid: 25)
[2025-05-27 13:40:03 +0000] [24] [ERROR] Worker (pid:25) exited with code 3
[2025-05-27 13:40:03 +0000] [26] [ERROR] Exception in worker process
Traceback (most recent call last):
  File "/usr/local/lib/python3.11/site-packages/gunicorn/arbiter.py", line 609, in spawn_worker
    worker.init_process()
  File "/usr/local/lib/python3.11/site-packages/gunicorn/workers/ggevent.py", line 147, in init_process
    super().init_process()
  File "/usr/local/lib/python3.11/site-packages/gunicorn/workers/base.py", line 134, in init_process
    self.load_wsgi()
  File "/usr/local/lib/python3.11/site-packages/gunicorn/workers/base.py", line 146, in load_wsgi
    self.wsgi = self.app.wsgi()
                ^^^^^^^^^^^^^^^
  File "/usr/local/lib/python3.11/site-packages/gunicorn/app/base.py", line 67, in wsgi
    self.callable = self.load()
                    ^^^^^^^^^^^
  File "/usr/local/lib/python3.11/site-packages/gunicorn/app/wsgiapp.py", line 58, in load
    return self.load_wsgiapp()
           ^^^^^^^^^^^^^^^^^^^
  File "/usr/local/lib/python3.11/site-packages/gunicorn/app/wsgiapp.py", line 48, in load_wsgiapp
    return util.import_app(self.app_uri)
           ^^^^^^^^^^^^^^^^^^^^^^^^^^^^^
  File "/usr/local/lib/python3.11/site-packages/gunicorn/util.py", line 371, in import_app
    mod = importlib.import_module(module)
          ^^^^^^^^^^^^^^^^^^^^^^^^^^^^^^^
  File "/usr/local/lib/python3.11/importlib/__init__.py", line 126, in import_module
    return _bootstrap._gcd_import(name[level:], package, level)
           ^^^^^^^^^^^^^^^^^^^^^^^^^^^^^^^^^^^^^^^^^^^^^^^^^^^^
  File "<frozen importlib._bootstrap>", line 1204, in _gcd_import
  File "<frozen importlib._bootstrap>", line 1176, in _find_and_load
  File "<frozen importlib._bootstrap>", line 1147, in _find_and_load_unlocked
  File "<frozen importlib._bootstrap>", line 690, in _load_unlocked
  File "<frozen importlib._bootstrap_external>", line 936, in exec_module
  File "<frozen importlib._bootstrap_external>", line 1074, in get_code
  File "<frozen importlib._bootstrap_external>", line 1004, in source_to_code
  File "<frozen importlib._bootstrap>", line 241, in _call_with_frames_removed
  File "/app/gongle-web/app.py", line 15
    app.config['SQLALCHEMY_DATABASE_URI'] = os.getenv('DATABASE_URL')'sqlite:////tmp/gongle.db'
                                                                     ^^^^^^^^^^^^^^^^^^^^^^^^^^
SyntaxError: invalid syntax
[2025-05-27 13:40:03 +0000] [26] [INFO] Worker exiting (pid: 26)
[2025-05-27 13:40:03 +0000] [24] [ERROR] Worker (pid:26) exited with code 3
Traceback (most recent call last):
  File "/usr/local/lib/python3.11/site-packages/gunicorn/arbiter.py", line 202, in run
    self.manage_workers()
  File "/usr/local/lib/python3.11/site-packages/gunicorn/arbiter.py", line 571, in manage_workers
    self.spawn_workers()
  File "/usr/local/lib/python3.11/site-packages/gunicorn/arbiter.py", line 643, in spawn_workers
    time.sleep(0.1 * random.random())
  File "/usr/local/lib/python3.11/site-packages/gunicorn/arbiter.py", line 242, in handle_chld
    self.reap_workers()
  File "/usr/local/lib/python3.11/site-packages/gunicorn/arbiter.py", line 530, in reap_workers
    raise HaltServer(reason, self.WORKER_BOOT_ERROR)
gunicorn.errors.HaltServer: <HaltServer 'Worker failed to boot.' 3>

During handling of the above exception, another exception occurred:

Traceback (most recent call last):
  File "/usr/local/bin/gunicorn", line 8, in <module>
    sys.exit(run())
             ^^^^^
  File "/usr/local/lib/python3.11/site-packages/gunicorn/app/wsgiapp.py", line 67, in run
    WSGIApplication("%(prog)s [OPTIONS] [APP_MODULE]").run()
  File "/usr/local/lib/python3.11/site-packages/gunicorn/app/base.py", line 236, in run
    super().run()
  File "/usr/local/lib/python3.11/site-packages/gunicorn/app/base.py", line 72, in run
    Arbiter(self).run()
  File "/usr/local/lib/python3.11/site-packages/gunicorn/arbiter.py", line 229, in run
    self.halt(reason=inst.reason, exit_status=inst.exit_status)
  File "/usr/local/lib/python3.11/site-packages/gunicorn/arbiter.py", line 342, in halt
    self.stop()
  File "/usr/local/lib/python3.11/site-packages/gunicorn/arbiter.py", line 396, in stop
    time.sleep(0.1)
  File "/usr/local/lib/python3.11/site-packages/gunicorn/arbiter.py", line 242, in handle_chld
    self.reap_workers()
  File "/usr/local/lib/python3.11/site-packages/gunicorn/arbiter.py", line 530, in reap_workers
    raise HaltServer(reason, self.WORKER_BOOT_ERROR)
gunicorn.errors.HaltServer: <HaltServer 'Worker failed to boot.' 3>
[2025-05-27 13:40:05 +0000] [27] [INFO] Starting gunicorn 21.2.0
[2025-05-27 13:40:05 +0000] [27] [INFO] Listening at: http://127.0.0.1:5000 (27)
[2025-05-27 13:40:05 +0000] [27] [INFO] Using worker: gevent
[2025-05-27 13:40:05 +0000] [28] [INFO] Booting worker with pid: 28
[2025-05-27 13:40:05 +0000] [29] [INFO] Booting worker with pid: 29
[2025-05-27 13:40:05 +0000] [28] [ERROR] Exception in worker process
Traceback (most recent call last):
  File "/usr/local/lib/python3.11/site-packages/gunicorn/arbiter.py", line 609, in spawn_worker
    worker.init_process()
  File "/usr/local/lib/python3.11/site-packages/gunicorn/workers/ggevent.py", line 147, in init_process
    super().init_process()
  File "/usr/local/lib/python3.11/site-packages/gunicorn/workers/base.py", line 134, in init_process
    self.load_wsgi()
  File "/usr/local/lib/python3.11/site-packages/gunicorn/workers/base.py", line 146, in load_wsgi
    self.wsgi = self.app.wsgi()
                ^^^^^^^^^^^^^^^
  File "/usr/local/lib/python3.11/site-packages/gunicorn/app/base.py", line 67, in wsgi
    self.callable = self.load()
                    ^^^^^^^^^^^
  File "/usr/local/lib/python3.11/site-packages/gunicorn/app/wsgiapp.py", line 58, in load
    return self.load_wsgiapp()
           ^^^^^^^^^^^^^^^^^^^
  File "/usr/local/lib/python3.11/site-packages/gunicorn/app/wsgiapp.py", line 48, in load_wsgiapp
    return util.import_app(self.app_uri)
           ^^^^^^^^^^^^^^^^^^^^^^^^^^^^^
  File "/usr/local/lib/python3.11/site-packages/gunicorn/util.py", line 371, in import_app
    mod = importlib.import_module(module)
          ^^^^^^^^^^^^^^^^^^^^^^^^^^^^^^^
  File "/usr/local/lib/python3.11/importlib/__init__.py", line 126, in import_module
    return _bootstrap._gcd_import(name[level:], package, level)
           ^^^^^^^^^^^^^^^^^^^^^^^^^^^^^^^^^^^^^^^^^^^^^^^^^^^^
  File "<frozen importlib._bootstrap>", line 1204, in _gcd_import
  File "<frozen importlib._bootstrap>", line 1176, in _find_and_load
  File "<frozen importlib._bootstrap>", line 1147, in _find_and_load_unlocked
  File "<frozen importlib._bootstrap>", line 690, in _load_unlocked
  File "<frozen importlib._bootstrap_external>", line 936, in exec_module
  File "<frozen importlib._bootstrap_external>", line 1074, in get_code
  File "<frozen importlib._bootstrap_external>", line 1004, in source_to_code
  File "<frozen importlib._bootstrap>", line 241, in _call_with_frames_removed
  File "/app/gongle-web/app.py", line 15
    app.config['SQLALCHEMY_DATABASE_URI'] = os.getenv('DATABASE_URL')'sqlite:////tmp/gongle.db'
                                                                     ^^^^^^^^^^^^^^^^^^^^^^^^^^
SyntaxError: invalid syntax
[2025-05-27 13:40:05 +0000] [28] [INFO] Worker exiting (pid: 28)
[2025-05-27 13:40:05 +0000] [29] [ERROR] Exception in worker process
Traceback (most recent call last):
  File "/usr/local/lib/python3.11/site-packages/gunicorn/arbiter.py", line 609, in spawn_worker
    worker.init_process()
  File "/usr/local/lib/python3.11/site-packages/gunicorn/workers/ggevent.py", line 147, in init_process
    super().init_process()
  File "/usr/local/lib/python3.11/site-packages/gunicorn/workers/base.py", line 134, in init_process
    self.load_wsgi()
  File "/usr/local/lib/python3.11/site-packages/gunicorn/workers/base.py", line 146, in load_wsgi
    self.wsgi = self.app.wsgi()
                ^^^^^^^^^^^^^^^
  File "/usr/local/lib/python3.11/site-packages/gunicorn/app/base.py", line 67, in wsgi
    self.callable = self.load()
                    ^^^^^^^^^^^
  File "/usr/local/lib/python3.11/site-packages/gunicorn/app/wsgiapp.py", line 58, in load
    return self.load_wsgiapp()
           ^^^^^^^^^^^^^^^^^^^
  File "/usr/local/lib/python3.11/site-packages/gunicorn/app/wsgiapp.py", line 48, in load_wsgiapp
    return util.import_app(self.app_uri)
           ^^^^^^^^^^^^^^^^^^^^^^^^^^^^^
  File "/usr/local/lib/python3.11/site-packages/gunicorn/util.py", line 371, in import_app
    mod = importlib.import_module(module)
          ^^^^^^^^^^^^^^^^^^^^^^^^^^^^^^^
  File "/usr/local/lib/python3.11/importlib/__init__.py", line 126, in import_module
    return _bootstrap._gcd_import(name[level:], package, level)
           ^^^^^^^^^^^^^^^^^^^^^^^^^^^^^^^^^^^^^^^^^^^^^^^^^^^^
  File "<frozen importlib._bootstrap>", line 1204, in _gcd_import
  File "<frozen importlib._bootstrap>", line 1176, in _find_and_load
  File "<frozen importlib._bootstrap>", line 1147, in _find_and_load_unlocked
  File "<frozen importlib._bootstrap>", line 690, in _load_unlocked
  File "<frozen importlib._bootstrap_external>", line 936, in exec_module
  File "<frozen importlib._bootstrap_external>", line 1074, in get_code
  File "<frozen importlib._bootstrap_external>", line 1004, in source_to_code
  File "<frozen importlib._bootstrap>", line 241, in _call_with_frames_removed
  File "/app/gongle-web/app.py", line 15
    app.config['SQLALCHEMY_DATABASE_URI'] = os.getenv('DATABASE_URL')'sqlite:////tmp/gongle.db'
                                                                     ^^^^^^^^^^^^^^^^^^^^^^^^^^
SyntaxError: invalid syntax
[2025-05-27 13:40:05 +0000] [29] [INFO] Worker exiting (pid: 29)
[2025-05-27 13:40:05 +0000] [30] [INFO] Booting worker with pid: 30
[2025-05-27 13:40:05 +0000] [27] [ERROR] Worker (pid:28) exited with code 3
[2025-05-27 13:40:05 +0000] [27] [ERROR] Worker (pid:29) was sent SIGTERM!
[2025-05-27 13:40:05 +0000] [30] [ERROR] Exception in worker process
Traceback (most recent call last):
  File "/usr/local/lib/python3.11/site-packages/gunicorn/arbiter.py", line 609, in spawn_worker
    worker.init_process()
  File "/usr/local/lib/python3.11/site-packages/gunicorn/workers/ggevent.py", line 147, in init_process
    super().init_process()
  File "/usr/local/lib/python3.11/site-packages/gunicorn/workers/base.py", line 134, in init_process
    self.load_wsgi()
  File "/usr/local/lib/python3.11/site-packages/gunicorn/workers/base.py", line 146, in load_wsgi
    self.wsgi = self.app.wsgi()
                ^^^^^^^^^^^^^^^
  File "/usr/local/lib/python3.11/site-packages/gunicorn/app/base.py", line 67, in wsgi
    self.callable = self.load()
                    ^^^^^^^^^^^
  File "/usr/local/lib/python3.11/site-packages/gunicorn/app/wsgiapp.py", line 58, in load
    return self.load_wsgiapp()
           ^^^^^^^^^^^^^^^^^^^
  File "/usr/local/lib/python3.11/site-packages/gunicorn/app/wsgiapp.py", line 48, in load_wsgiapp
    return util.import_app(self.app_uri)
           ^^^^^^^^^^^^^^^^^^^^^^^^^^^^^
  File "/usr/local/lib/python3.11/site-packages/gunicorn/util.py", line 371, in import_app
    mod = importlib.import_module(module)
          ^^^^^^^^^^^^^^^^^^^^^^^^^^^^^^^
  File "/usr/local/lib/python3.11/importlib/__init__.py", line 126, in import_module
    return _bootstrap._gcd_import(name[level:], package, level)
           ^^^^^^^^^^^^^^^^^^^^^^^^^^^^^^^^^^^^^^^^^^^^^^^^^^^^
  File "<frozen importlib._bootstrap>", line 1204, in _gcd_import
  File "<frozen importlib._bootstrap>", line 1176, in _find_and_load
  File "<frozen importlib._bootstrap>", line 1147, in _find_and_load_unlocked
  File "<frozen importlib._bootstrap>", line 690, in _load_unlocked
  File "<frozen importlib._bootstrap_external>", line 936, in exec_module
  File "<frozen importlib._bootstrap_external>", line 1074, in get_code
  File "<frozen importlib._bootstrap_external>", line 1004, in source_to_code
  File "<frozen importlib._bootstrap>", line 241, in _call_with_frames_removed
  File "/app/gongle-web/app.py", line 15
    app.config['SQLALCHEMY_DATABASE_URI'] = os.getenv('DATABASE_URL')'sqlite:////tmp/gongle.db'
                                                                     ^^^^^^^^^^^^^^^^^^^^^^^^^^
SyntaxError: invalid syntax
[2025-05-27 13:40:05 +0000] [30] [INFO] Worker exiting (pid: 30)
[2025-05-27 13:40:05 +0000] [27] [ERROR] Worker (pid:30) exited with code 3
Traceback (most recent call last):
  File "/usr/local/lib/python3.11/site-packages/gunicorn/arbiter.py", line 202, in run
    self.manage_workers()
  File "/usr/local/lib/python3.11/site-packages/gunicorn/arbiter.py", line 571, in manage_workers
    self.spawn_workers()
  File "/usr/local/lib/python3.11/site-packages/gunicorn/arbiter.py", line 643, in spawn_workers
    time.sleep(0.1 * random.random())
  File "/usr/local/lib/python3.11/site-packages/gunicorn/arbiter.py", line 242, in handle_chld
    self.reap_workers()
  File "/usr/local/lib/python3.11/site-packages/gunicorn/arbiter.py", line 530, in reap_workers
    raise HaltServer(reason, self.WORKER_BOOT_ERROR)
gunicorn.errors.HaltServer: <HaltServer 'Worker failed to boot.' 3>

During handling of the above exception, another exception occurred:

Traceback (most recent call last):
  File "/usr/local/bin/gunicorn", line 8, in <module>
    sys.exit(run())
             ^^^^^
  File "/usr/local/lib/python3.11/site-packages/gunicorn/app/wsgiapp.py", line 67, in run
    WSGIApplication("%(prog)s [OPTIONS] [APP_MODULE]").run()
  File "/usr/local/lib/python3.11/site-packages/gunicorn/app/base.py", line 236, in run
    super().run()
  File "/usr/local/lib/python3.11/site-packages/gunicorn/app/base.py", line 72, in run
    Arbiter(self).run()
  File "/usr/local/lib/python3.11/site-packages/gunicorn/arbiter.py", line 229, in run
    self.halt(reason=inst.reason, exit_status=inst.exit_status)
  File "/usr/local/lib/python3.11/site-packages/gunicorn/arbiter.py", line 342, in halt
    self.stop()
  File "/usr/local/lib/python3.11/site-packages/gunicorn/arbiter.py", line 396, in stop
    time.sleep(0.1)
  File "/usr/local/lib/python3.11/site-packages/gunicorn/arbiter.py", line 242, in handle_chld
    self.reap_workers()
  File "/usr/local/lib/python3.11/site-packages/gunicorn/arbiter.py", line 530, in reap_workers
    raise HaltServer(reason, self.WORKER_BOOT_ERROR)
gunicorn.errors.HaltServer: <HaltServer 'Worker failed to boot.' 3>
[2025-05-27 13:40:09 +0000] [31] [INFO] Starting gunicorn 21.2.0
[2025-05-27 13:40:09 +0000] [31] [INFO] Listening at: http://127.0.0.1:5000 (31)
[2025-05-27 13:40:09 +0000] [31] [INFO] Using worker: gevent
[2025-05-27 13:40:09 +0000] [32] [INFO] Booting worker with pid: 32
[2025-05-27 13:40:09 +0000] [33] [INFO] Booting worker with pid: 33
[2025-05-27 13:40:09 +0000] [32] [ERROR] Exception in worker process
Traceback (most recent call last):
  File "/usr/local/lib/python3.11/site-packages/gunicorn/arbiter.py", line 609, in spawn_worker
    worker.init_process()
  File "/usr/local/lib/python3.11/site-packages/gunicorn/workers/ggevent.py", line 147, in init_process
    super().init_process()
  File "/usr/local/lib/python3.11/site-packages/gunicorn/workers/base.py", line 134, in init_process
    self.load_wsgi()
  File "/usr/local/lib/python3.11/site-packages/gunicorn/workers/base.py", line 146, in load_wsgi
    self.wsgi = self.app.wsgi()
                ^^^^^^^^^^^^^^^
  File "/usr/local/lib/python3.11/site-packages/gunicorn/app/base.py", line 67, in wsgi
    self.callable = self.load()
                    ^^^^^^^^^^^
  File "/usr/local/lib/python3.11/site-packages/gunicorn/app/wsgiapp.py", line 58, in load
    return self.load_wsgiapp()
           ^^^^^^^^^^^^^^^^^^^
  File "/usr/local/lib/python3.11/site-packages/gunicorn/app/wsgiapp.py", line 48, in load_wsgiapp
    return util.import_app(self.app_uri)
           ^^^^^^^^^^^^^^^^^^^^^^^^^^^^^
  File "/usr/local/lib/python3.11/site-packages/gunicorn/util.py", line 371, in import_app
    mod = importlib.import_module(module)
          ^^^^^^^^^^^^^^^^^^^^^^^^^^^^^^^
  File "/usr/local/lib/python3.11/importlib/__init__.py", line 126, in import_module
    return _bootstrap._gcd_import(name[level:], package, level)
           ^^^^^^^^^^^^^^^^^^^^^^^^^^^^^^^^^^^^^^^^^^^^^^^^^^^^
  File "<frozen importlib._bootstrap>", line 1204, in _gcd_import
  File "<frozen importlib._bootstrap>", line 1176, in _find_and_load
  File "<frozen importlib._bootstrap>", line 1147, in _find_and_load_unlocked
  File "<frozen importlib._bootstrap>", line 690, in _load_unlocked
  File "<frozen importlib._bootstrap_external>", line 936, in exec_module
  File "<frozen importlib._bootstrap_external>", line 1074, in get_code
  File "<frozen importlib._bootstrap_external>", line 1004, in source_to_code
  File "<frozen importlib._bootstrap>", line 241, in _call_with_frames_removed
  File "/app/gongle-web/app.py", line 15
    app.config['SQLALCHEMY_DATABASE_URI'] = os.getenv('DATABASE_URL')'sqlite:////tmp/gongle.db'
                                                                     ^^^^^^^^^^^^^^^^^^^^^^^^^^
SyntaxError: invalid syntax
[2025-05-27 13:40:09 +0000] [32] [INFO] Worker exiting (pid: 32)
[2025-05-27 13:40:09 +0000] [33] [ERROR] Exception in worker process
Traceback (most recent call last):
  File "/usr/local/lib/python3.11/site-packages/gunicorn/arbiter.py", line 609, in spawn_worker
    worker.init_process()
  File "/usr/local/lib/python3.11/site-packages/gunicorn/workers/ggevent.py", line 147, in init_process
    super().init_process()
  File "/usr/local/lib/python3.11/site-packages/gunicorn/workers/base.py", line 134, in init_process
    self.load_wsgi()
  File "/usr/local/lib/python3.11/site-packages/gunicorn/workers/base.py", line 146, in load_wsgi
    self.wsgi = self.app.wsgi()
                ^^^^^^^^^^^^^^^
  File "/usr/local/lib/python3.11/site-packages/gunicorn/app/base.py", line 67, in wsgi
    self.callable = self.load()
                    ^^^^^^^^^^^
  File "/usr/local/lib/python3.11/site-packages/gunicorn/app/wsgiapp.py", line 58, in load
    return self.load_wsgiapp()
           ^^^^^^^^^^^^^^^^^^^
  File "/usr/local/lib/python3.11/site-packages/gunicorn/app/wsgiapp.py", line 48, in load_wsgiapp
    return util.import_app(self.app_uri)
           ^^^^^^^^^^^^^^^^^^^^^^^^^^^^^
  File "/usr/local/lib/python3.11/site-packages/gunicorn/util.py", line 371, in import_app
    mod = importlib.import_module(module)
          ^^^^^^^^^^^^^^^^^^^^^^^^^^^^^^^
  File "/usr/local/lib/python3.11/importlib/__init__.py", line 126, in import_module
    return _bootstrap._gcd_import(name[level:], package, level)
           ^^^^^^^^^^^^^^^^^^^^^^^^^^^^^^^^^^^^^^^^^^^^^^^^^^^^
  File "<frozen importlib._bootstrap>", line 1204, in _gcd_import
  File "<frozen importlib._bootstrap>", line 1176, in _find_and_load
  File "<frozen importlib._bootstrap>", line 1147, in _find_and_load_unlocked
  File "<frozen importlib._bootstrap>", line 690, in _load_unlocked
  File "<frozen importlib._bootstrap_external>", line 936, in exec_module
  File "<frozen importlib._bootstrap_external>", line 1074, in get_code
  File "<frozen importlib._bootstrap_external>", line 1004, in source_to_code
  File "<frozen importlib._bootstrap>", line 241, in _call_with_frames_removed
  File "/app/gongle-web/app.py", line 15
    app.config['SQLALCHEMY_DATABASE_URI'] = os.getenv('DATABASE_URL')'sqlite:////tmp/gongle.db'
                                                                     ^^^^^^^^^^^^^^^^^^^^^^^^^^
SyntaxError: invalid syntax
[2025-05-27 13:40:09 +0000] [33] [INFO] Worker exiting (pid: 33)
[2025-05-27 13:40:09 +0000] [34] [INFO] Booting worker with pid: 34
[2025-05-27 13:40:09 +0000] [35] [INFO] Booting worker with pid: 35
[2025-05-27 13:40:09 +0000] [31] [ERROR] Worker (pid:32) exited with code 3
[2025-05-27 13:40:09 +0000] [31] [ERROR] Worker (pid:33) was sent SIGTERM!
[2025-05-27 13:40:09 +0000] [34] [ERROR] Exception in worker process
Traceback (most recent call last):
  File "/usr/local/lib/python3.11/site-packages/gunicorn/arbiter.py", line 609, in spawn_worker
    worker.init_process()
  File "/usr/local/lib/python3.11/site-packages/gunicorn/workers/ggevent.py", line 147, in init_process
    super().init_process()
  File "/usr/local/lib/python3.11/site-packages/gunicorn/workers/base.py", line 134, in init_process
    self.load_wsgi()
  File "/usr/local/lib/python3.11/site-packages/gunicorn/workers/base.py", line 146, in load_wsgi
    self.wsgi = self.app.wsgi()
                ^^^^^^^^^^^^^^^
  File "/usr/local/lib/python3.11/site-packages/gunicorn/app/base.py", line 67, in wsgi
    self.callable = self.load()
                    ^^^^^^^^^^^
  File "/usr/local/lib/python3.11/site-packages/gunicorn/app/wsgiapp.py", line 58, in load
    return self.load_wsgiapp()
           ^^^^^^^^^^^^^^^^^^^
  File "/usr/local/lib/python3.11/site-packages/gunicorn/app/wsgiapp.py", line 48, in load_wsgiapp
    return util.import_app(self.app_uri)
           ^^^^^^^^^^^^^^^^^^^^^^^^^^^^^
  File "/usr/local/lib/python3.11/site-packages/gunicorn/util.py", line 371, in import_app
    mod = importlib.import_module(module)
          ^^^^^^^^^^^^^^^^^^^^^^^^^^^^^^^
  File "/usr/local/lib/python3.11/importlib/__init__.py", line 126, in import_module
    return _bootstrap._gcd_import(name[level:], package, level)
           ^^^^^^^^^^^^^^^^^^^^^^^^^^^^^^^^^^^^^^^^^^^^^^^^^^^^
  File "<frozen importlib._bootstrap>", line 1204, in _gcd_import
  File "<frozen importlib._bootstrap>", line 1176, in _find_and_load
  File "<frozen importlib._bootstrap>", line 1147, in _find_and_load_unlocked
  File "<frozen importlib._bootstrap>", line 690, in _load_unlocked
  File "<frozen importlib._bootstrap_external>", line 936, in exec_module
  File "<frozen importlib._bootstrap_external>", line 1074, in get_code
  File "<frozen importlib._bootstrap_external>", line 1004, in source_to_code
  File "<frozen importlib._bootstrap>", line 241, in _call_with_frames_removed
  File "/app/gongle-web/app.py", line 15
    app.config['SQLALCHEMY_DATABASE_URI'] = os.getenv('DATABASE_URL')'sqlite:////tmp/gongle.db'
                                                                     ^^^^^^^^^^^^^^^^^^^^^^^^^^
SyntaxError: invalid syntax
[2025-05-27 13:40:09 +0000] [34] [INFO] Worker exiting (pid: 34)
[2025-05-27 13:40:09 +0000] [35] [ERROR] Exception in worker process
Traceback (most recent call last):
  File "/usr/local/lib/python3.11/site-packages/gunicorn/arbiter.py", line 609, in spawn_worker
    worker.init_process()
  File "/usr/local/lib/python3.11/site-packages/gunicorn/workers/ggevent.py", line 147, in init_process
    super().init_process()
  File "/usr/local/lib/python3.11/site-packages/gunicorn/workers/base.py", line 134, in init_process
    self.load_wsgi()
  File "/usr/local/lib/python3.11/site-packages/gunicorn/workers/base.py", line 146, in load_wsgi
    self.wsgi = self.app.wsgi()
                ^^^^^^^^^^^^^^^
  File "/usr/local/lib/python3.11/site-packages/gunicorn/app/base.py", line 67, in wsgi
    self.callable = self.load()
                    ^^^^^^^^^^^
  File "/usr/local/lib/python3.11/site-packages/gunicorn/app/wsgiapp.py", line 58, in load
    return self.load_wsgiapp()
           ^^^^^^^^^^^^^^^^^^^
  File "/usr/local/lib/python3.11/site-packages/gunicorn/app/wsgiapp.py", line 48, in load_wsgiapp
    return util.import_app(self.app_uri)
           ^^^^^^^^^^^^^^^^^^^^^^^^^^^^^
  File "/usr/local/lib/python3.11/site-packages/gunicorn/util.py", line 371, in import_app
    mod = importlib.import_module(module)
          ^^^^^^^^^^^^^^^^^^^^^^^^^^^^^^^
  File "/usr/local/lib/python3.11/importlib/__init__.py", line 126, in import_module
    return _bootstrap._gcd_import(name[level:], package, level)
           ^^^^^^^^^^^^^^^^^^^^^^^^^^^^^^^^^^^^^^^^^^^^^^^^^^^^
  File "<frozen importlib._bootstrap>", line 1204, in _gcd_import
  File "<frozen importlib._bootstrap>", line 1176, in _find_and_load
  File "<frozen importlib._bootstrap>", line 1147, in _find_and_load_unlocked
  File "<frozen importlib._bootstrap>", line 690, in _load_unlocked
  File "<frozen importlib._bootstrap_external>", line 936, in exec_module
  File "<frozen importlib._bootstrap_external>", line 1074, in get_code
  File "<frozen importlib._bootstrap_external>", line 1004, in source_to_code
  File "<frozen importlib._bootstrap>", line 241, in _call_with_frames_removed
  File "/app/gongle-web/app.py", line 15
    app.config['SQLALCHEMY_DATABASE_URI'] = os.getenv('DATABASE_URL')'sqlite:////tmp/gongle.db'
                                                                     ^^^^^^^^^^^^^^^^^^^^^^^^^^
SyntaxError: invalid syntax
[2025-05-27 13:40:09 +0000] [35] [INFO] Worker exiting (pid: 35)
[2025-05-27 13:40:09 +0000] [31] [ERROR] Worker (pid:34) exited with code 3
Traceback (most recent call last):
  File "/usr/local/lib/python3.11/site-packages/gunicorn/arbiter.py", line 202, in run
    self.manage_workers()
  File "/usr/local/lib/python3.11/site-packages/gunicorn/arbiter.py", line 571, in manage_workers
    self.spawn_workers()
  File "/usr/local/lib/python3.11/site-packages/gunicorn/arbiter.py", line 643, in spawn_workers
    time.sleep(0.1 * random.random())
  File "/usr/local/lib/python3.11/site-packages/gunicorn/arbiter.py", line 242, in handle_chld
    self.reap_workers()
  File "/usr/local/lib/python3.11/site-packages/gunicorn/arbiter.py", line 530, in reap_workers
    raise HaltServer(reason, self.WORKER_BOOT_ERROR)
gunicorn.errors.HaltServer: <HaltServer 'Worker failed to boot.' 3>

During handling of the above exception, another exception occurred:

Traceback (most recent call last):
  File "/usr/local/bin/gunicorn", line 8, in <module>
    sys.exit(run())
             ^^^^^
  File "/usr/local/lib/python3.11/site-packages/gunicorn/app/wsgiapp.py", line 67, in run
    WSGIApplication("%(prog)s [OPTIONS] [APP_MODULE]").run()
  File "/usr/local/lib/python3.11/site-packages/gunicorn/app/base.py", line 236, in run
    super().run()
  File "/usr/local/lib/python3.11/site-packages/gunicorn/app/base.py", line 72, in run
    Arbiter(self).run()
  File "/usr/local/lib/python3.11/site-packages/gunicorn/arbiter.py", line 229, in run
    self.halt(reason=inst.reason, exit_status=inst.exit_status)
  File "/usr/local/lib/python3.11/site-packages/gunicorn/arbiter.py", line 342, in halt
    self.stop()
  File "/usr/local/lib/python3.11/site-packages/gunicorn/arbiter.py", line 396, in stop
    time.sleep(0.1)
  File "/usr/local/lib/python3.11/site-packages/gunicorn/arbiter.py", line 242, in handle_chld
    self.reap_workers()
  File "/usr/local/lib/python3.11/site-packages/gunicorn/arbiter.py", line 530, in reap_workers
    raise HaltServer(reason, self.WORKER_BOOT_ERROR)
gunicorn.errors.HaltServer: <HaltServer 'Worker failed to boot.' 3>
[2025-05-27 13:46:28 +0000] [8] [INFO] Starting gunicorn 21.2.0
[2025-05-27 13:46:28 +0000] [8] [INFO] Listening at: http://127.0.0.1:5000 (8)
[2025-05-27 13:46:28 +0000] [8] [INFO] Using worker: gevent
[2025-05-27 13:46:28 +0000] [22] [INFO] Booting worker with pid: 22
[2025-05-27 13:46:28 +0000] [23] [INFO] Booting worker with pid: 23
[2025-05-27 13:46:28 +0000] [24] [INFO] Booting worker with pid: 24
[2025-05-27 13:46:28 +0000] [25] [INFO] Booting worker with pid: 25
[2025-05-27 13:46:28 +0000] [23] [ERROR] Exception in worker process
Traceback (most recent call last):
  File "/usr/local/lib/python3.11/site-packages/gunicorn/arbiter.py", line 609, in spawn_worker
    worker.init_process()
  File "/usr/local/lib/python3.11/site-packages/gunicorn/workers/ggevent.py", line 147, in init_process
    super().init_process()
  File "/usr/local/lib/python3.11/site-packages/gunicorn/workers/base.py", line 134, in init_process
    self.load_wsgi()
  File "/usr/local/lib/python3.11/site-packages/gunicorn/workers/base.py", line 146, in load_wsgi
    self.wsgi = self.app.wsgi()
                ^^^^^^^^^^^^^^^
  File "/usr/local/lib/python3.11/site-packages/gunicorn/app/base.py", line 67, in wsgi
    self.callable = self.load()
                    ^^^^^^^^^^^
  File "/usr/local/lib/python3.11/site-packages/gunicorn/app/wsgiapp.py", line 58, in load
    return self.load_wsgiapp()
           ^^^^^^^^^^^^^^^^^^^
  File "/usr/local/lib/python3.11/site-packages/gunicorn/app/wsgiapp.py", line 48, in load_wsgiapp
    return util.import_app(self.app_uri)
           ^^^^^^^^^^^^^^^^^^^^^^^^^^^^^
  File "/usr/local/lib/python3.11/site-packages/gunicorn/util.py", line 371, in import_app
    mod = importlib.import_module(module)
          ^^^^^^^^^^^^^^^^^^^^^^^^^^^^^^^
  File "/usr/local/lib/python3.11/importlib/__init__.py", line 126, in import_module
    return _bootstrap._gcd_import(name[level:], package, level)
           ^^^^^^^^^^^^^^^^^^^^^^^^^^^^^^^^^^^^^^^^^^^^^^^^^^^^
  File "<frozen importlib._bootstrap>", line 1204, in _gcd_import
  File "<frozen importlib._bootstrap>", line 1176, in _find_and_load
  File "<frozen importlib._bootstrap>", line 1147, in _find_and_load_unlocked
  File "<frozen importlib._bootstrap>", line 690, in _load_unlocked
  File "<frozen importlib._bootstrap_external>", line 940, in exec_module
  File "<frozen importlib._bootstrap>", line 241, in _call_with_frames_removed
  File "/app/gongle-web/app.py", line 2, in <module>
    from flask_sqlalchemy import SQLAlchemy
ModuleNotFoundError: No module named 'flask_sqlalchemy'
[2025-05-27 13:46:28 +0000] [23] [INFO] Worker exiting (pid: 23)
[2025-05-27 13:46:28 +0000] [22] [ERROR] Exception in worker process
Traceback (most recent call last):
  File "/usr/local/lib/python3.11/site-packages/gunicorn/arbiter.py", line 609, in spawn_worker
    worker.init_process()
  File "/usr/local/lib/python3.11/site-packages/gunicorn/workers/ggevent.py", line 147, in init_process
    super().init_process()
  File "/usr/local/lib/python3.11/site-packages/gunicorn/workers/base.py", line 134, in init_process
    self.load_wsgi()
  File "/usr/local/lib/python3.11/site-packages/gunicorn/workers/base.py", line 146, in load_wsgi
    self.wsgi = self.app.wsgi()
                ^^^^^^^^^^^^^^^
  File "/usr/local/lib/python3.11/site-packages/gunicorn/app/base.py", line 67, in wsgi
    self.callable = self.load()
                    ^^^^^^^^^^^
  File "/usr/local/lib/python3.11/site-packages/gunicorn/app/wsgiapp.py", line 58, in load
    return self.load_wsgiapp()
           ^^^^^^^^^^^^^^^^^^^
  File "/usr/local/lib/python3.11/site-packages/gunicorn/app/wsgiapp.py", line 48, in load_wsgiapp
    return util.import_app(self.app_uri)
           ^^^^^^^^^^^^^^^^^^^^^^^^^^^^^
  File "/usr/local/lib/python3.11/site-packages/gunicorn/util.py", line 371, in import_app
    mod = importlib.import_module(module)
          ^^^^^^^^^^^^^^^^^^^^^^^^^^^^^^^
  File "/usr/local/lib/python3.11/importlib/__init__.py", line 126, in import_module
    return _bootstrap._gcd_import(name[level:], package, level)
           ^^^^^^^^^^^^^^^^^^^^^^^^^^^^^^^^^^^^^^^^^^^^^^^^^^^^
  File "<frozen importlib._bootstrap>", line 1204, in _gcd_import
  File "<frozen importlib._bootstrap>", line 1176, in _find_and_load
  File "<frozen importlib._bootstrap>", line 1147, in _find_and_load_unlocked
  File "<frozen importlib._bootstrap>", line 690, in _load_unlocked
  File "<frozen importlib._bootstrap_external>", line 940, in exec_module
  File "<frozen importlib._bootstrap>", line 241, in _call_with_frames_removed
  File "/app/gongle-web/app.py", line 2, in <module>
    from flask_sqlalchemy import SQLAlchemy
ModuleNotFoundError: No module named 'flask_sqlalchemy'
[2025-05-27 13:46:28 +0000] [22] [INFO] Worker exiting (pid: 22)
[2025-05-27 13:46:28 +0000] [8] [ERROR] Worker (pid:23) exited with code 3
[2025-05-27 13:46:28 +0000] [8] [ERROR] Worker (pid:22) was sent SIGTERM!
[2025-05-27 13:46:28 +0000] [24] [ERROR] Exception in worker process
Traceback (most recent call last):
  File "/usr/local/lib/python3.11/site-packages/gunicorn/arbiter.py", line 609, in spawn_worker
    worker.init_process()
  File "/usr/local/lib/python3.11/site-packages/gunicorn/workers/ggevent.py", line 147, in init_process
    super().init_process()
  File "/usr/local/lib/python3.11/site-packages/gunicorn/workers/base.py", line 134, in init_process
    self.load_wsgi()
  File "/usr/local/lib/python3.11/site-packages/gunicorn/workers/base.py", line 146, in load_wsgi
    self.wsgi = self.app.wsgi()
                ^^^^^^^^^^^^^^^
  File "/usr/local/lib/python3.11/site-packages/gunicorn/app/base.py", line 67, in wsgi
    self.callable = self.load()
                    ^^^^^^^^^^^
  File "/usr/local/lib/python3.11/site-packages/gunicorn/app/wsgiapp.py", line 58, in load
    return self.load_wsgiapp()
           ^^^^^^^^^^^^^^^^^^^
  File "/usr/local/lib/python3.11/site-packages/gunicorn/app/wsgiapp.py", line 48, in load_wsgiapp
    return util.import_app(self.app_uri)
           ^^^^^^^^^^^^^^^^^^^^^^^^^^^^^
  File "/usr/local/lib/python3.11/site-packages/gunicorn/util.py", line 371, in import_app
    mod = importlib.import_module(module)
          ^^^^^^^^^^^^^^^^^^^^^^^^^^^^^^^
  File "/usr/local/lib/python3.11/importlib/__init__.py", line 126, in import_module
    return _bootstrap._gcd_import(name[level:], package, level)
           ^^^^^^^^^^^^^^^^^^^^^^^^^^^^^^^^^^^^^^^^^^^^^^^^^^^^
  File "<frozen importlib._bootstrap>", line 1204, in _gcd_import
  File "<frozen importlib._bootstrap>", line 1176, in _find_and_load
  File "<frozen importlib._bootstrap>", line 1147, in _find_and_load_unlocked
  File "<frozen importlib._bootstrap>", line 690, in _load_unlocked
  File "<frozen importlib._bootstrap_external>", line 940, in exec_module
  File "<frozen importlib._bootstrap>", line 241, in _call_with_frames_removed
  File "/app/gongle-web/app.py", line 2, in <module>
    from flask_sqlalchemy import SQLAlchemy
ModuleNotFoundError: No module named 'flask_sqlalchemy'
[2025-05-27 13:46:28 +0000] [24] [INFO] Worker exiting (pid: 24)
[2025-05-27 13:46:28 +0000] [25] [ERROR] Exception in worker process
Traceback (most recent call last):
  File "/usr/local/lib/python3.11/site-packages/gunicorn/arbiter.py", line 609, in spawn_worker
    worker.init_process()
  File "/usr/local/lib/python3.11/site-packages/gunicorn/workers/ggevent.py", line 147, in init_process
    super().init_process()
  File "/usr/local/lib/python3.11/site-packages/gunicorn/workers/base.py", line 134, in init_process
    self.load_wsgi()
  File "/usr/local/lib/python3.11/site-packages/gunicorn/workers/base.py", line 146, in load_wsgi
    self.wsgi = self.app.wsgi()
                ^^^^^^^^^^^^^^^
  File "/usr/local/lib/python3.11/site-packages/gunicorn/app/base.py", line 67, in wsgi
    self.callable = self.load()
                    ^^^^^^^^^^^
  File "/usr/local/lib/python3.11/site-packages/gunicorn/app/wsgiapp.py", line 58, in load
    return self.load_wsgiapp()
           ^^^^^^^^^^^^^^^^^^^
  File "/usr/local/lib/python3.11/site-packages/gunicorn/app/wsgiapp.py", line 48, in load_wsgiapp
    return util.import_app(self.app_uri)
           ^^^^^^^^^^^^^^^^^^^^^^^^^^^^^
  File "/usr/local/lib/python3.11/site-packages/gunicorn/util.py", line 371, in import_app
    mod = importlib.import_module(module)
          ^^^^^^^^^^^^^^^^^^^^^^^^^^^^^^^
  File "/usr/local/lib/python3.11/importlib/__init__.py", line 126, in import_module
    return _bootstrap._gcd_import(name[level:], package, level)
           ^^^^^^^^^^^^^^^^^^^^^^^^^^^^^^^^^^^^^^^^^^^^^^^^^^^^
  File "<frozen importlib._bootstrap>", line 1204, in _gcd_import
  File "<frozen importlib._bootstrap>", line 1176, in _find_and_load
  File "<frozen importlib._bootstrap>", line 1147, in _find_and_load_unlocked
  File "<frozen importlib._bootstrap>", line 690, in _load_unlocked
  File "<frozen importlib._bootstrap_external>", line 940, in exec_module
  File "<frozen importlib._bootstrap>", line 241, in _call_with_frames_removed
  File "/app/gongle-web/app.py", line 2, in <module>
    from flask_sqlalchemy import SQLAlchemy
ModuleNotFoundError: No module named 'flask_sqlalchemy'
[2025-05-27 13:46:28 +0000] [25] [INFO] Worker exiting (pid: 25)
[2025-05-27 13:46:28 +0000] [8] [ERROR] Worker (pid:24) exited with code 3
Traceback (most recent call last):
  File "/usr/local/lib/python3.11/site-packages/gunicorn/arbiter.py", line 209, in run
    self.sleep()
  File "/usr/local/lib/python3.11/site-packages/gunicorn/arbiter.py", line 360, in sleep
    ready = select.select([self.PIPE[0]], [], [], 1.0)
            ^^^^^^^^^^^^^^^^^^^^^^^^^^^^^^^^^^^^^^^^^^
  File "/usr/local/lib/python3.11/site-packages/gunicorn/arbiter.py", line 242, in handle_chld
    self.reap_workers()
  File "/usr/local/lib/python3.11/site-packages/gunicorn/arbiter.py", line 530, in reap_workers
    raise HaltServer(reason, self.WORKER_BOOT_ERROR)
gunicorn.errors.HaltServer: <HaltServer 'Worker failed to boot.' 3>

During handling of the above exception, another exception occurred:

Traceback (most recent call last):
  File "/usr/local/bin/gunicorn", line 8, in <module>
    sys.exit(run())
             ^^^^^
  File "/usr/local/lib/python3.11/site-packages/gunicorn/app/wsgiapp.py", line 67, in run
    WSGIApplication("%(prog)s [OPTIONS] [APP_MODULE]").run()
  File "/usr/local/lib/python3.11/site-packages/gunicorn/app/base.py", line 236, in run
    super().run()
  File "/usr/local/lib/python3.11/site-packages/gunicorn/app/base.py", line 72, in run
    Arbiter(self).run()
  File "/usr/local/lib/python3.11/site-packages/gunicorn/arbiter.py", line 229, in run
    self.halt(reason=inst.reason, exit_status=inst.exit_status)
  File "/usr/local/lib/python3.11/site-packages/gunicorn/arbiter.py", line 342, in halt
    self.stop()
  File "/usr/local/lib/python3.11/site-packages/gunicorn/arbiter.py", line 396, in stop
    time.sleep(0.1)
  File "/usr/local/lib/python3.11/site-packages/gunicorn/arbiter.py", line 242, in handle_chld
    self.reap_workers()
  File "/usr/local/lib/python3.11/site-packages/gunicorn/arbiter.py", line 530, in reap_workers
    raise HaltServer(reason, self.WORKER_BOOT_ERROR)
gunicorn.errors.HaltServer: <HaltServer 'Worker failed to boot.' 3>
[2025-05-27 13:46:29 +0000] [26] [INFO] Starting gunicorn 21.2.0
[2025-05-27 13:46:29 +0000] [26] [INFO] Listening at: http://127.0.0.1:5000 (26)
[2025-05-27 13:46:29 +0000] [26] [INFO] Using worker: gevent
[2025-05-27 13:46:29 +0000] [27] [INFO] Booting worker with pid: 27
[2025-05-27 13:46:29 +0000] [28] [INFO] Booting worker with pid: 28
[2025-05-27 13:46:29 +0000] [27] [ERROR] Exception in worker process
Traceback (most recent call last):
  File "/usr/local/lib/python3.11/site-packages/gunicorn/arbiter.py", line 609, in spawn_worker
    worker.init_process()
  File "/usr/local/lib/python3.11/site-packages/gunicorn/workers/ggevent.py", line 147, in init_process
    super().init_process()
  File "/usr/local/lib/python3.11/site-packages/gunicorn/workers/base.py", line 134, in init_process
    self.load_wsgi()
  File "/usr/local/lib/python3.11/site-packages/gunicorn/workers/base.py", line 146, in load_wsgi
    self.wsgi = self.app.wsgi()
                ^^^^^^^^^^^^^^^
  File "/usr/local/lib/python3.11/site-packages/gunicorn/app/base.py", line 67, in wsgi
    self.callable = self.load()
                    ^^^^^^^^^^^
  File "/usr/local/lib/python3.11/site-packages/gunicorn/app/wsgiapp.py", line 58, in load
    return self.load_wsgiapp()
           ^^^^^^^^^^^^^^^^^^^
  File "/usr/local/lib/python3.11/site-packages/gunicorn/app/wsgiapp.py", line 48, in load_wsgiapp
    return util.import_app(self.app_uri)
           ^^^^^^^^^^^^^^^^^^^^^^^^^^^^^
  File "/usr/local/lib/python3.11/site-packages/gunicorn/util.py", line 371, in import_app
    mod = importlib.import_module(module)
          ^^^^^^^^^^^^^^^^^^^^^^^^^^^^^^^
  File "/usr/local/lib/python3.11/importlib/__init__.py", line 126, in import_module
    return _bootstrap._gcd_import(name[level:], package, level)
           ^^^^^^^^^^^^^^^^^^^^^^^^^^^^^^^^^^^^^^^^^^^^^^^^^^^^
  File "<frozen importlib._bootstrap>", line 1204, in _gcd_import
  File "<frozen importlib._bootstrap>", line 1176, in _find_and_load
  File "<frozen importlib._bootstrap>", line 1147, in _find_and_load_unlocked
  File "<frozen importlib._bootstrap>", line 690, in _load_unlocked
  File "<frozen importlib._bootstrap_external>", line 940, in exec_module
  File "<frozen importlib._bootstrap>", line 241, in _call_with_frames_removed
  File "/app/gongle-web/app.py", line 2, in <module>
    from flask_sqlalchemy import SQLAlchemy
ModuleNotFoundError: No module named 'flask_sqlalchemy'
[2025-05-27 13:46:29 +0000] [27] [INFO] Worker exiting (pid: 27)
[2025-05-27 13:46:29 +0000] [29] [INFO] Booting worker with pid: 29
[2025-05-27 13:46:29 +0000] [26] [ERROR] Worker (pid:27) exited with code 3
[2025-05-27 13:46:29 +0000] [28] [ERROR] Exception in worker process
Traceback (most recent call last):
  File "/usr/local/lib/python3.11/site-packages/gunicorn/arbiter.py", line 609, in spawn_worker
    worker.init_process()
  File "/usr/local/lib/python3.11/site-packages/gunicorn/workers/ggevent.py", line 147, in init_process
    super().init_process()
  File "/usr/local/lib/python3.11/site-packages/gunicorn/workers/base.py", line 134, in init_process
    self.load_wsgi()
  File "/usr/local/lib/python3.11/site-packages/gunicorn/workers/base.py", line 146, in load_wsgi
    self.wsgi = self.app.wsgi()
                ^^^^^^^^^^^^^^^
  File "/usr/local/lib/python3.11/site-packages/gunicorn/app/base.py", line 67, in wsgi
    self.callable = self.load()
                    ^^^^^^^^^^^
  File "/usr/local/lib/python3.11/site-packages/gunicorn/app/wsgiapp.py", line 58, in load
    return self.load_wsgiapp()
           ^^^^^^^^^^^^^^^^^^^
  File "/usr/local/lib/python3.11/site-packages/gunicorn/app/wsgiapp.py", line 48, in load_wsgiapp
    return util.import_app(self.app_uri)
           ^^^^^^^^^^^^^^^^^^^^^^^^^^^^^
  File "/usr/local/lib/python3.11/site-packages/gunicorn/util.py", line 371, in import_app
    mod = importlib.import_module(module)
          ^^^^^^^^^^^^^^^^^^^^^^^^^^^^^^^
  File "/usr/local/lib/python3.11/importlib/__init__.py", line 126, in import_module
    return _bootstrap._gcd_import(name[level:], package, level)
           ^^^^^^^^^^^^^^^^^^^^^^^^^^^^^^^^^^^^^^^^^^^^^^^^^^^^
  File "<frozen importlib._bootstrap>", line 1204, in _gcd_import
  File "<frozen importlib._bootstrap>", line 1176, in _find_and_load
  File "<frozen importlib._bootstrap>", line 1147, in _find_and_load_unlocked
  File "<frozen importlib._bootstrap>", line 690, in _load_unlocked
  File "<frozen importlib._bootstrap_external>", line 940, in exec_module
  File "<frozen importlib._bootstrap>", line 241, in _call_with_frames_removed
  File "/app/gongle-web/app.py", line 2, in <module>
    from flask_sqlalchemy import SQLAlchemy
ModuleNotFoundError: No module named 'flask_sqlalchemy'
[2025-05-27 13:46:29 +0000] [28] [INFO] Worker exiting (pid: 28)
[2025-05-27 13:46:29 +0000] [26] [ERROR] Worker (pid:28) exited with code 3
Traceback (most recent call last):
  File "/usr/local/lib/python3.11/site-packages/gunicorn/arbiter.py", line 202, in run
    self.manage_workers()
  File "/usr/local/lib/python3.11/site-packages/gunicorn/arbiter.py", line 571, in manage_workers
    self.spawn_workers()
  File "/usr/local/lib/python3.11/site-packages/gunicorn/arbiter.py", line 643, in spawn_workers
    time.sleep(0.1 * random.random())
  File "/usr/local/lib/python3.11/site-packages/gunicorn/arbiter.py", line 242, in handle_chld
    self.reap_workers()
  File "/usr/local/lib/python3.11/site-packages/gunicorn/arbiter.py", line 530, in reap_workers
    raise HaltServer(reason, self.WORKER_BOOT_ERROR)
gunicorn.errors.HaltServer: <HaltServer 'Worker failed to boot.' 3>

During handling of the above exception, another exception occurred:

Traceback (most recent call last):
  File "/usr/local/bin/gunicorn", line 8, in <module>
    sys.exit(run())
             ^^^^^
  File "/usr/local/lib/python3.11/site-packages/gunicorn/app/wsgiapp.py", line 67, in run
    WSGIApplication("%(prog)s [OPTIONS] [APP_MODULE]").run()
  File "/usr/local/lib/python3.11/site-packages/gunicorn/app/base.py", line 236, in run
    super().run()
  File "/usr/local/lib/python3.11/site-packages/gunicorn/app/base.py", line 72, in run
    Arbiter(self).run()
  File "/usr/local/lib/python3.11/site-packages/gunicorn/arbiter.py", line 229, in run
    self.halt(reason=inst.reason, exit_status=inst.exit_status)
  File "/usr/local/lib/python3.11/site-packages/gunicorn/arbiter.py", line 342, in halt
    self.stop()
  File "/usr/local/lib/python3.11/site-packages/gunicorn/arbiter.py", line 396, in stop
    time.sleep(0.1)
  File "/usr/local/lib/python3.11/site-packages/gunicorn/arbiter.py", line 242, in handle_chld
    self.reap_workers()
  File "/usr/local/lib/python3.11/site-packages/gunicorn/arbiter.py", line 530, in reap_workers
    raise HaltServer(reason, self.WORKER_BOOT_ERROR)
gunicorn.errors.HaltServer: <HaltServer 'Worker failed to boot.' 3>
[2025-05-27 13:46:29 +0000] [29] [ERROR] Exception in worker process
Traceback (most recent call last):
  File "/usr/local/lib/python3.11/site-packages/gunicorn/arbiter.py", line 609, in spawn_worker
    worker.init_process()
  File "/usr/local/lib/python3.11/site-packages/gunicorn/workers/ggevent.py", line 147, in init_process
    super().init_process()
  File "/usr/local/lib/python3.11/site-packages/gunicorn/workers/base.py", line 134, in init_process
    self.load_wsgi()
  File "/usr/local/lib/python3.11/site-packages/gunicorn/workers/base.py", line 146, in load_wsgi
    self.wsgi = self.app.wsgi()
                ^^^^^^^^^^^^^^^
  File "/usr/local/lib/python3.11/site-packages/gunicorn/app/base.py", line 67, in wsgi
    self.callable = self.load()
                    ^^^^^^^^^^^
  File "/usr/local/lib/python3.11/site-packages/gunicorn/app/wsgiapp.py", line 58, in load
    return self.load_wsgiapp()
           ^^^^^^^^^^^^^^^^^^^
  File "/usr/local/lib/python3.11/site-packages/gunicorn/app/wsgiapp.py", line 48, in load_wsgiapp
    return util.import_app(self.app_uri)
           ^^^^^^^^^^^^^^^^^^^^^^^^^^^^^
  File "/usr/local/lib/python3.11/site-packages/gunicorn/util.py", line 371, in import_app
    mod = importlib.import_module(module)
          ^^^^^^^^^^^^^^^^^^^^^^^^^^^^^^^
  File "/usr/local/lib/python3.11/importlib/__init__.py", line 126, in import_module
    return _bootstrap._gcd_import(name[level:], package, level)
           ^^^^^^^^^^^^^^^^^^^^^^^^^^^^^^^^^^^^^^^^^^^^^^^^^^^^
  File "<frozen importlib._bootstrap>", line 1204, in _gcd_import
  File "<frozen importlib._bootstrap>", line 1176, in _find_and_load
  File "<frozen importlib._bootstrap>", line 1147, in _find_and_load_unlocked
  File "<frozen importlib._bootstrap>", line 690, in _load_unlocked
  File "<frozen importlib._bootstrap_external>", line 940, in exec_module
  File "<frozen importlib._bootstrap>", line 241, in _call_with_frames_removed
  File "/app/gongle-web/app.py", line 2, in <module>
    from flask_sqlalchemy import SQLAlchemy
ModuleNotFoundError: No module named 'flask_sqlalchemy'
[2025-05-27 13:46:29 +0000] [29] [INFO] Worker exiting (pid: 29)
[2025-05-27 13:46:32 +0000] [30] [INFO] Starting gunicorn 21.2.0
[2025-05-27 13:46:32 +0000] [30] [INFO] Listening at: http://127.0.0.1:5000 (30)
[2025-05-27 13:46:32 +0000] [30] [INFO] Using worker: gevent
[2025-05-27 13:46:32 +0000] [31] [INFO] Booting worker with pid: 31
[2025-05-27 13:46:32 +0000] [32] [INFO] Booting worker with pid: 32
[2025-05-27 13:46:32 +0000] [33] [INFO] Booting worker with pid: 33
[2025-05-27 13:46:32 +0000] [34] [INFO] Booting worker with pid: 34
[2025-05-27 13:46:32 +0000] [31] [ERROR] Exception in worker process
Traceback (most recent call last):
  File "/usr/local/lib/python3.11/site-packages/gunicorn/arbiter.py", line 609, in spawn_worker
    worker.init_process()
  File "/usr/local/lib/python3.11/site-packages/gunicorn/workers/ggevent.py", line 147, in init_process
    super().init_process()
  File "/usr/local/lib/python3.11/site-packages/gunicorn/workers/base.py", line 134, in init_process
    self.load_wsgi()
  File "/usr/local/lib/python3.11/site-packages/gunicorn/workers/base.py", line 146, in load_wsgi
    self.wsgi = self.app.wsgi()
                ^^^^^^^^^^^^^^^
  File "/usr/local/lib/python3.11/site-packages/gunicorn/app/base.py", line 67, in wsgi
    self.callable = self.load()
                    ^^^^^^^^^^^
  File "/usr/local/lib/python3.11/site-packages/gunicorn/app/wsgiapp.py", line 58, in load
    return self.load_wsgiapp()
           ^^^^^^^^^^^^^^^^^^^
  File "/usr/local/lib/python3.11/site-packages/gunicorn/app/wsgiapp.py", line 48, in load_wsgiapp
    return util.import_app(self.app_uri)
           ^^^^^^^^^^^^^^^^^^^^^^^^^^^^^
  File "/usr/local/lib/python3.11/site-packages/gunicorn/util.py", line 371, in import_app
    mod = importlib.import_module(module)
          ^^^^^^^^^^^^^^^^^^^^^^^^^^^^^^^
  File "/usr/local/lib/python3.11/importlib/__init__.py", line 126, in import_module
    return _bootstrap._gcd_import(name[level:], package, level)
           ^^^^^^^^^^^^^^^^^^^^^^^^^^^^^^^^^^^^^^^^^^^^^^^^^^^^
  File "<frozen importlib._bootstrap>", line 1204, in _gcd_import
  File "<frozen importlib._bootstrap>", line 1176, in _find_and_load
  File "<frozen importlib._bootstrap>", line 1147, in _find_and_load_unlocked
  File "<frozen importlib._bootstrap>", line 690, in _load_unlocked
  File "<frozen importlib._bootstrap_external>", line 940, in exec_module
  File "<frozen importlib._bootstrap>", line 241, in _call_with_frames_removed
  File "/app/gongle-web/app.py", line 2, in <module>
    from flask_sqlalchemy import SQLAlchemy
ModuleNotFoundError: No module named 'flask_sqlalchemy'
[2025-05-27 13:46:32 +0000] [31] [INFO] Worker exiting (pid: 31)
[2025-05-27 13:46:32 +0000] [32] [ERROR] Exception in worker process
Traceback (most recent call last):
  File "/usr/local/lib/python3.11/site-packages/gunicorn/arbiter.py", line 609, in spawn_worker
    worker.init_process()
  File "/usr/local/lib/python3.11/site-packages/gunicorn/workers/ggevent.py", line 147, in init_process
    super().init_process()
  File "/usr/local/lib/python3.11/site-packages/gunicorn/workers/base.py", line 134, in init_process
    self.load_wsgi()
  File "/usr/local/lib/python3.11/site-packages/gunicorn/workers/base.py", line 146, in load_wsgi
    self.wsgi = self.app.wsgi()
                ^^^^^^^^^^^^^^^
  File "/usr/local/lib/python3.11/site-packages/gunicorn/app/base.py", line 67, in wsgi
    self.callable = self.load()
                    ^^^^^^^^^^^
  File "/usr/local/lib/python3.11/site-packages/gunicorn/app/wsgiapp.py", line 58, in load
    return self.load_wsgiapp()
           ^^^^^^^^^^^^^^^^^^^
  File "/usr/local/lib/python3.11/site-packages/gunicorn/app/wsgiapp.py", line 48, in load_wsgiapp
    return util.import_app(self.app_uri)
           ^^^^^^^^^^^^^^^^^^^^^^^^^^^^^
  File "/usr/local/lib/python3.11/site-packages/gunicorn/util.py", line 371, in import_app
    mod = importlib.import_module(module)
          ^^^^^^^^^^^^^^^^^^^^^^^^^^^^^^^
  File "/usr/local/lib/python3.11/importlib/__init__.py", line 126, in import_module
    return _bootstrap._gcd_import(name[level:], package, level)
           ^^^^^^^^^^^^^^^^^^^^^^^^^^^^^^^^^^^^^^^^^^^^^^^^^^^^
  File "<frozen importlib._bootstrap>", line 1204, in _gcd_import
  File "<frozen importlib._bootstrap>", line 1176, in _find_and_load
  File "<frozen importlib._bootstrap>", line 1147, in _find_and_load_unlocked
  File "<frozen importlib._bootstrap>", line 690, in _load_unlocked
  File "<frozen importlib._bootstrap_external>", line 940, in exec_module
  File "<frozen importlib._bootstrap>", line 241, in _call_with_frames_removed
  File "/app/gongle-web/app.py", line 2, in <module>
    from flask_sqlalchemy import SQLAlchemy
ModuleNotFoundError: No module named 'flask_sqlalchemy'
[2025-05-27 13:46:32 +0000] [32] [INFO] Worker exiting (pid: 32)
[2025-05-27 13:46:32 +0000] [33] [ERROR] Exception in worker process
Traceback (most recent call last):
  File "/usr/local/lib/python3.11/site-packages/gunicorn/arbiter.py", line 609, in spawn_worker
    worker.init_process()
  File "/usr/local/lib/python3.11/site-packages/gunicorn/workers/ggevent.py", line 147, in init_process
    super().init_process()
  File "/usr/local/lib/python3.11/site-packages/gunicorn/workers/base.py", line 134, in init_process
    self.load_wsgi()
  File "/usr/local/lib/python3.11/site-packages/gunicorn/workers/base.py", line 146, in load_wsgi
    self.wsgi = self.app.wsgi()
                ^^^^^^^^^^^^^^^
  File "/usr/local/lib/python3.11/site-packages/gunicorn/app/base.py", line 67, in wsgi
    self.callable = self.load()
                    ^^^^^^^^^^^
  File "/usr/local/lib/python3.11/site-packages/gunicorn/app/wsgiapp.py", line 58, in load
    return self.load_wsgiapp()
           ^^^^^^^^^^^^^^^^^^^
  File "/usr/local/lib/python3.11/site-packages/gunicorn/app/wsgiapp.py", line 48, in load_wsgiapp
    return util.import_app(self.app_uri)
           ^^^^^^^^^^^^^^^^^^^^^^^^^^^^^
  File "/usr/local/lib/python3.11/site-packages/gunicorn/util.py", line 371, in import_app
    mod = importlib.import_module(module)
          ^^^^^^^^^^^^^^^^^^^^^^^^^^^^^^^
  File "/usr/local/lib/python3.11/importlib/__init__.py", line 126, in import_module
    return _bootstrap._gcd_import(name[level:], package, level)
           ^^^^^^^^^^^^^^^^^^^^^^^^^^^^^^^^^^^^^^^^^^^^^^^^^^^^
  File "<frozen importlib._bootstrap>", line 1204, in _gcd_import
  File "<frozen importlib._bootstrap>", line 1176, in _find_and_load
  File "<frozen importlib._bootstrap>", line 1147, in _find_and_load_unlocked
  File "<frozen importlib._bootstrap>", line 690, in _load_unlocked
  File "<frozen importlib._bootstrap_external>", line 940, in exec_module
  File "<frozen importlib._bootstrap>", line 241, in _call_with_frames_removed
  File "/app/gongle-web/app.py", line 2, in <module>
    from flask_sqlalchemy import SQLAlchemy
ModuleNotFoundError: No module named 'flask_sqlalchemy'
[2025-05-27 13:46:32 +0000] [33] [INFO] Worker exiting (pid: 33)
[2025-05-27 13:46:32 +0000] [30] [ERROR] Worker (pid:32) exited with code 3
[2025-05-27 13:46:32 +0000] [30] [ERROR] Worker (pid:31) was sent SIGTERM!
[2025-05-27 13:46:32 +0000] [30] [ERROR] Worker (pid:33) was sent SIGTERM!
[2025-05-27 13:46:32 +0000] [34] [ERROR] Exception in worker process
Traceback (most recent call last):
  File "/usr/local/lib/python3.11/site-packages/gunicorn/arbiter.py", line 609, in spawn_worker
    worker.init_process()
  File "/usr/local/lib/python3.11/site-packages/gunicorn/workers/ggevent.py", line 147, in init_process
    super().init_process()
  File "/usr/local/lib/python3.11/site-packages/gunicorn/workers/base.py", line 134, in init_process
    self.load_wsgi()
  File "/usr/local/lib/python3.11/site-packages/gunicorn/workers/base.py", line 146, in load_wsgi
    self.wsgi = self.app.wsgi()
                ^^^^^^^^^^^^^^^
  File "/usr/local/lib/python3.11/site-packages/gunicorn/app/base.py", line 67, in wsgi
    self.callable = self.load()
                    ^^^^^^^^^^^
  File "/usr/local/lib/python3.11/site-packages/gunicorn/app/wsgiapp.py", line 58, in load
    return self.load_wsgiapp()
           ^^^^^^^^^^^^^^^^^^^
  File "/usr/local/lib/python3.11/site-packages/gunicorn/app/wsgiapp.py", line 48, in load_wsgiapp
    return util.import_app(self.app_uri)
           ^^^^^^^^^^^^^^^^^^^^^^^^^^^^^
  File "/usr/local/lib/python3.11/site-packages/gunicorn/util.py", line 371, in import_app
    mod = importlib.import_module(module)
          ^^^^^^^^^^^^^^^^^^^^^^^^^^^^^^^
  File "/usr/local/lib/python3.11/importlib/__init__.py", line 126, in import_module
    return _bootstrap._gcd_import(name[level:], package, level)
           ^^^^^^^^^^^^^^^^^^^^^^^^^^^^^^^^^^^^^^^^^^^^^^^^^^^^
  File "<frozen importlib._bootstrap>", line 1204, in _gcd_import
  File "<frozen importlib._bootstrap>", line 1176, in _find_and_load
  File "<frozen importlib._bootstrap>", line 1147, in _find_and_load_unlocked
  File "<frozen importlib._bootstrap>", line 690, in _load_unlocked
  File "<frozen importlib._bootstrap_external>", line 940, in exec_module
  File "<frozen importlib._bootstrap>", line 241, in _call_with_frames_removed
  File "/app/gongle-web/app.py", line 2, in <module>
    from flask_sqlalchemy import SQLAlchemy
ModuleNotFoundError: No module named 'flask_sqlalchemy'
[2025-05-27 13:46:32 +0000] [34] [INFO] Worker exiting (pid: 34)
[2025-05-27 13:46:32 +0000] [30] [ERROR] Worker (pid:34) exited with code 3
Traceback (most recent call last):
  File "/usr/local/lib/python3.11/site-packages/gunicorn/arbiter.py", line 209, in run
    self.sleep()
  File "/usr/local/lib/python3.11/site-packages/gunicorn/arbiter.py", line 360, in sleep
    ready = select.select([self.PIPE[0]], [], [], 1.0)
            ^^^^^^^^^^^^^^^^^^^^^^^^^^^^^^^^^^^^^^^^^^
  File "/usr/local/lib/python3.11/site-packages/gunicorn/arbiter.py", line 242, in handle_chld
    self.reap_workers()
  File "/usr/local/lib/python3.11/site-packages/gunicorn/arbiter.py", line 530, in reap_workers
    raise HaltServer(reason, self.WORKER_BOOT_ERROR)
gunicorn.errors.HaltServer: <HaltServer 'Worker failed to boot.' 3>

During handling of the above exception, another exception occurred:

Traceback (most recent call last):
  File "/usr/local/bin/gunicorn", line 8, in <module>
    sys.exit(run())
             ^^^^^
  File "/usr/local/lib/python3.11/site-packages/gunicorn/app/wsgiapp.py", line 67, in run
    WSGIApplication("%(prog)s [OPTIONS] [APP_MODULE]").run()
  File "/usr/local/lib/python3.11/site-packages/gunicorn/app/base.py", line 236, in run
    super().run()
  File "/usr/local/lib/python3.11/site-packages/gunicorn/app/base.py", line 72, in run
    Arbiter(self).run()
  File "/usr/local/lib/python3.11/site-packages/gunicorn/arbiter.py", line 229, in run
    self.halt(reason=inst.reason, exit_status=inst.exit_status)
  File "/usr/local/lib/python3.11/site-packages/gunicorn/arbiter.py", line 342, in halt
    self.stop()
  File "/usr/local/lib/python3.11/site-packages/gunicorn/arbiter.py", line 396, in stop
    time.sleep(0.1)
  File "/usr/local/lib/python3.11/site-packages/gunicorn/arbiter.py", line 242, in handle_chld
    self.reap_workers()
  File "/usr/local/lib/python3.11/site-packages/gunicorn/arbiter.py", line 530, in reap_workers
    raise HaltServer(reason, self.WORKER_BOOT_ERROR)
gunicorn.errors.HaltServer: <HaltServer 'Worker failed to boot.' 3>
[2025-05-27 13:46:35 +0000] [35] [INFO] Starting gunicorn 21.2.0
[2025-05-27 13:46:35 +0000] [35] [INFO] Listening at: http://127.0.0.1:5000 (35)
[2025-05-27 13:46:35 +0000] [35] [INFO] Using worker: gevent
[2025-05-27 13:46:35 +0000] [36] [INFO] Booting worker with pid: 36
[2025-05-27 13:46:35 +0000] [37] [INFO] Booting worker with pid: 37
[2025-05-27 13:46:35 +0000] [38] [INFO] Booting worker with pid: 38
[2025-05-27 13:46:35 +0000] [36] [ERROR] Exception in worker process
Traceback (most recent call last):
  File "/usr/local/lib/python3.11/site-packages/gunicorn/arbiter.py", line 609, in spawn_worker
    worker.init_process()
  File "/usr/local/lib/python3.11/site-packages/gunicorn/workers/ggevent.py", line 147, in init_process
    super().init_process()
  File "/usr/local/lib/python3.11/site-packages/gunicorn/workers/base.py", line 134, in init_process
    self.load_wsgi()
  File "/usr/local/lib/python3.11/site-packages/gunicorn/workers/base.py", line 146, in load_wsgi
    self.wsgi = self.app.wsgi()
                ^^^^^^^^^^^^^^^
  File "/usr/local/lib/python3.11/site-packages/gunicorn/app/base.py", line 67, in wsgi
    self.callable = self.load()
                    ^^^^^^^^^^^
  File "/usr/local/lib/python3.11/site-packages/gunicorn/app/wsgiapp.py", line 58, in load
    return self.load_wsgiapp()
           ^^^^^^^^^^^^^^^^^^^
  File "/usr/local/lib/python3.11/site-packages/gunicorn/app/wsgiapp.py", line 48, in load_wsgiapp
    return util.import_app(self.app_uri)
           ^^^^^^^^^^^^^^^^^^^^^^^^^^^^^
  File "/usr/local/lib/python3.11/site-packages/gunicorn/util.py", line 371, in import_app
    mod = importlib.import_module(module)
          ^^^^^^^^^^^^^^^^^^^^^^^^^^^^^^^
  File "/usr/local/lib/python3.11/importlib/__init__.py", line 126, in import_module
    return _bootstrap._gcd_import(name[level:], package, level)
           ^^^^^^^^^^^^^^^^^^^^^^^^^^^^^^^^^^^^^^^^^^^^^^^^^^^^
  File "<frozen importlib._bootstrap>", line 1204, in _gcd_import
  File "<frozen importlib._bootstrap>", line 1176, in _find_and_load
  File "<frozen importlib._bootstrap>", line 1147, in _find_and_load_unlocked
  File "<frozen importlib._bootstrap>", line 690, in _load_unlocked
  File "<frozen importlib._bootstrap_external>", line 940, in exec_module
  File "<frozen importlib._bootstrap>", line 241, in _call_with_frames_removed
  File "/app/gongle-web/app.py", line 2, in <module>
    from flask_sqlalchemy import SQLAlchemy
ModuleNotFoundError: No module named 'flask_sqlalchemy'
[2025-05-27 13:46:35 +0000] [36] [INFO] Worker exiting (pid: 36)
[2025-05-27 13:46:35 +0000] [39] [INFO] Booting worker with pid: 39
[2025-05-27 13:46:35 +0000] [37] [ERROR] Exception in worker process
Traceback (most recent call last):
  File "/usr/local/lib/python3.11/site-packages/gunicorn/arbiter.py", line 609, in spawn_worker
    worker.init_process()
  File "/usr/local/lib/python3.11/site-packages/gunicorn/workers/ggevent.py", line 147, in init_process
    super().init_process()
  File "/usr/local/lib/python3.11/site-packages/gunicorn/workers/base.py", line 134, in init_process
    self.load_wsgi()
  File "/usr/local/lib/python3.11/site-packages/gunicorn/workers/base.py", line 146, in load_wsgi
    self.wsgi = self.app.wsgi()
                ^^^^^^^^^^^^^^^
  File "/usr/local/lib/python3.11/site-packages/gunicorn/app/base.py", line 67, in wsgi
    self.callable = self.load()
                    ^^^^^^^^^^^
  File "/usr/local/lib/python3.11/site-packages/gunicorn/app/wsgiapp.py", line 58, in load
    return self.load_wsgiapp()
           ^^^^^^^^^^^^^^^^^^^
  File "/usr/local/lib/python3.11/site-packages/gunicorn/app/wsgiapp.py", line 48, in load_wsgiapp
    return util.import_app(self.app_uri)
           ^^^^^^^^^^^^^^^^^^^^^^^^^^^^^
  File "/usr/local/lib/python3.11/site-packages/gunicorn/util.py", line 371, in import_app
    mod = importlib.import_module(module)
          ^^^^^^^^^^^^^^^^^^^^^^^^^^^^^^^
  File "/usr/local/lib/python3.11/importlib/__init__.py", line 126, in import_module
    return _bootstrap._gcd_import(name[level:], package, level)
           ^^^^^^^^^^^^^^^^^^^^^^^^^^^^^^^^^^^^^^^^^^^^^^^^^^^^
  File "<frozen importlib._bootstrap>", line 1204, in _gcd_import
  File "<frozen importlib._bootstrap>", line 1176, in _find_and_load
  File "<frozen importlib._bootstrap>", line 1147, in _find_and_load_unlocked
  File "<frozen importlib._bootstrap>", line 690, in _load_unlocked
  File "<frozen importlib._bootstrap_external>", line 940, in exec_module
  File "<frozen importlib._bootstrap>", line 241, in _call_with_frames_removed
  File "/app/gongle-web/app.py", line 2, in <module>
    from flask_sqlalchemy import SQLAlchemy
ModuleNotFoundError: No module named 'flask_sqlalchemy'
[2025-05-27 13:46:35 +0000] [37] [INFO] Worker exiting (pid: 37)
[2025-05-27 13:46:35 +0000] [35] [ERROR] Worker (pid:36) exited with code 3
[2025-05-27 13:46:35 +0000] [35] [ERROR] Worker (pid:37) was sent SIGTERM!
[2025-05-27 13:46:35 +0000] [38] [ERROR] Exception in worker process
Traceback (most recent call last):
  File "/usr/local/lib/python3.11/site-packages/gunicorn/arbiter.py", line 609, in spawn_worker
    worker.init_process()
  File "/usr/local/lib/python3.11/site-packages/gunicorn/workers/ggevent.py", line 147, in init_process
    super().init_process()
  File "/usr/local/lib/python3.11/site-packages/gunicorn/workers/base.py", line 134, in init_process
    self.load_wsgi()
  File "/usr/local/lib/python3.11/site-packages/gunicorn/workers/base.py", line 146, in load_wsgi
    self.wsgi = self.app.wsgi()
                ^^^^^^^^^^^^^^^
  File "/usr/local/lib/python3.11/site-packages/gunicorn/app/base.py", line 67, in wsgi
    self.callable = self.load()
                    ^^^^^^^^^^^
  File "/usr/local/lib/python3.11/site-packages/gunicorn/app/wsgiapp.py", line 58, in load
    return self.load_wsgiapp()
           ^^^^^^^^^^^^^^^^^^^
  File "/usr/local/lib/python3.11/site-packages/gunicorn/app/wsgiapp.py", line 48, in load_wsgiapp
    return util.import_app(self.app_uri)
           ^^^^^^^^^^^^^^^^^^^^^^^^^^^^^
  File "/usr/local/lib/python3.11/site-packages/gunicorn/util.py", line 371, in import_app
    mod = importlib.import_module(module)
          ^^^^^^^^^^^^^^^^^^^^^^^^^^^^^^^
  File "/usr/local/lib/python3.11/importlib/__init__.py", line 126, in import_module
    return _bootstrap._gcd_import(name[level:], package, level)
           ^^^^^^^^^^^^^^^^^^^^^^^^^^^^^^^^^^^^^^^^^^^^^^^^^^^^
  File "<frozen importlib._bootstrap>", line 1204, in _gcd_import
  File "<frozen importlib._bootstrap>", line 1176, in _find_and_load
  File "<frozen importlib._bootstrap>", line 1147, in _find_and_load_unlocked
  File "<frozen importlib._bootstrap>", line 690, in _load_unlocked
  File "<frozen importlib._bootstrap_external>", line 940, in exec_module
  File "<frozen importlib._bootstrap>", line 241, in _call_with_frames_removed
  File "/app/gongle-web/app.py", line 2, in <module>
    from flask_sqlalchemy import SQLAlchemy
ModuleNotFoundError: No module named 'flask_sqlalchemy'
[2025-05-27 13:46:35 +0000] [38] [INFO] Worker exiting (pid: 38)
[2025-05-27 13:46:35 +0000] [35] [ERROR] Worker (pid:38) exited with code 3
Traceback (most recent call last):
  File "/usr/local/lib/python3.11/site-packages/gunicorn/arbiter.py", line 209, in run
    self.sleep()
  File "/usr/local/lib/python3.11/site-packages/gunicorn/arbiter.py", line 360, in sleep
    ready = select.select([self.PIPE[0]], [], [], 1.0)
            ^^^^^^^^^^^^^^^^^^^^^^^^^^^^^^^^^^^^^^^^^^
  File "/usr/local/lib/python3.11/site-packages/gunicorn/arbiter.py", line 242, in handle_chld
    self.reap_workers()
  File "/usr/local/lib/python3.11/site-packages/gunicorn/arbiter.py", line 530, in reap_workers
    raise HaltServer(reason, self.WORKER_BOOT_ERROR)
gunicorn.errors.HaltServer: <HaltServer 'Worker failed to boot.' 3>

During handling of the above exception, another exception occurred:

Traceback (most recent call last):
  File "/usr/local/bin/gunicorn", line 8, in <module>
    sys.exit(run())
             ^^^^^
  File "/usr/local/lib/python3.11/site-packages/gunicorn/app/wsgiapp.py", line 67, in run
    WSGIApplication("%(prog)s [OPTIONS] [APP_MODULE]").run()
  File "/usr/local/lib/python3.11/site-packages/gunicorn/app/base.py", line 236, in run
    super().run()
  File "/usr/local/lib/python3.11/site-packages/gunicorn/app/base.py", line 72, in run
    Arbiter(self).run()
  File "/usr/local/lib/python3.11/site-packages/gunicorn/arbiter.py", line 229, in run
    self.halt(reason=inst.reason, exit_status=inst.exit_status)
  File "/usr/local/lib/python3.11/site-packages/gunicorn/arbiter.py", line 342, in halt
    self.stop()
  File "/usr/local/lib/python3.11/site-packages/gunicorn/arbiter.py", line 396, in stop
    time.sleep(0.1)
  File "/usr/local/lib/python3.11/site-packages/gunicorn/arbiter.py", line 242, in handle_chld
    self.reap_workers()
  File "/usr/local/lib/python3.11/site-packages/gunicorn/arbiter.py", line 530, in reap_workers
    raise HaltServer(reason, self.WORKER_BOOT_ERROR)
gunicorn.errors.HaltServer: <HaltServer 'Worker failed to boot.' 3>
[2025-05-27 13:46:35 +0000] [39] [ERROR] Exception in worker process
Traceback (most recent call last):
  File "/usr/local/lib/python3.11/site-packages/gunicorn/arbiter.py", line 609, in spawn_worker
    worker.init_process()
  File "/usr/local/lib/python3.11/site-packages/gunicorn/workers/ggevent.py", line 147, in init_process
    super().init_process()
  File "/usr/local/lib/python3.11/site-packages/gunicorn/workers/base.py", line 134, in init_process
    self.load_wsgi()
  File "/usr/local/lib/python3.11/site-packages/gunicorn/workers/base.py", line 146, in load_wsgi
    self.wsgi = self.app.wsgi()
                ^^^^^^^^^^^^^^^
  File "/usr/local/lib/python3.11/site-packages/gunicorn/app/base.py", line 67, in wsgi
    self.callable = self.load()
                    ^^^^^^^^^^^
  File "/usr/local/lib/python3.11/site-packages/gunicorn/app/wsgiapp.py", line 58, in load
    return self.load_wsgiapp()
           ^^^^^^^^^^^^^^^^^^^
  File "/usr/local/lib/python3.11/site-packages/gunicorn/app/wsgiapp.py", line 48, in load_wsgiapp
    return util.import_app(self.app_uri)
           ^^^^^^^^^^^^^^^^^^^^^^^^^^^^^
  File "/usr/local/lib/python3.11/site-packages/gunicorn/util.py", line 371, in import_app
    mod = importlib.import_module(module)
          ^^^^^^^^^^^^^^^^^^^^^^^^^^^^^^^
  File "/usr/local/lib/python3.11/importlib/__init__.py", line 126, in import_module
    return _bootstrap._gcd_import(name[level:], package, level)
           ^^^^^^^^^^^^^^^^^^^^^^^^^^^^^^^^^^^^^^^^^^^^^^^^^^^^
  File "<frozen importlib._bootstrap>", line 1204, in _gcd_import
  File "<frozen importlib._bootstrap>", line 1176, in _find_and_load
  File "<frozen importlib._bootstrap>", line 1147, in _find_and_load_unlocked
  File "<frozen importlib._bootstrap>", line 690, in _load_unlocked
  File "<frozen importlib._bootstrap_external>", line 940, in exec_module
  File "<frozen importlib._bootstrap>", line 241, in _call_with_frames_removed
  File "/app/gongle-web/app.py", line 2, in <module>
    from flask_sqlalchemy import SQLAlchemy
ModuleNotFoundError: No module named 'flask_sqlalchemy'
[2025-05-27 13:46:35 +0000] [39] [INFO] Worker exiting (pid: 39)
[2025-05-27 13:51:12 +0000] [8] [INFO] Starting gunicorn 21.2.0
[2025-05-27 13:51:12 +0000] [8] [INFO] Listening at: http://127.0.0.1:5000 (8)
[2025-05-27 13:51:12 +0000] [8] [INFO] Using worker: gevent
[2025-05-27 13:51:12 +0000] [22] [INFO] Booting worker with pid: 22
[2025-05-27 13:51:12 +0000] [23] [INFO] Booting worker with pid: 23
[2025-05-27 13:51:13 +0000] [24] [INFO] Booting worker with pid: 24
[2025-05-27 13:51:13 +0000] [25] [INFO] Booting worker with pid: 25
